{"name": "lsst.ctrl.mpexec.cmdLineFwk", "asctime": "2022-09-01T20:11:10.591896+00:00", "message": "QuantumGraph contains 222480 quanta for 5 tasks, graph ID: '1662063033.8025286-69035'", "levelno": 20, "levelname": "INFO", "filename": "cmdLineFwk.py", "pathname": "/cvmfs/sw.lsst.eu/linux-x86_64/lsst_distrib/w_2022_36/conda/envs/lsst-scipipe-4.1.0/share/eups/Linux64/ctrl_mpexec/g5106228df7+1629eaad64/python/lsst/ctrl/mpexec/cmdLineFwk.py", "lineno": 581, "funcName": "makeGraph", "process": 69035, "processName": "MainProcess", "MDC": {}}
{"name": "lsst.daf.butler._butler", "asctime": "2022-09-06T19:20:27.501823+00:00", "message": "Failed to instantiate Butler from config file:///sdf/group/rubin/repo/main_20220411/butler.yaml.", "levelno": 40, "levelname": "ERROR", "filename": "_butler.py", "pathname": "/cvmfs/sw.lsst.eu/linux-x86_64/lsst_distrib/w_2022_36/conda/envs/lsst-scipipe-4.1.0/share/eups/Linux64/daf_butler/g3ee7dd65e6+24e5aa5155/python/lsst/daf/butler/_butler.py", "lineno": 295, "funcName": "__init__", "process": 116350, "processName": "MainProcess", "MDC": {}}
{"name": "lsst.daf.butler.cli.utils", "asctime": "2022-09-06T19:20:27.514908+00:00", "message": "Caught an exception, details are in traceback:", "levelno": 40, "levelname": "ERROR", "filename": "utils.py", "pathname": "/cvmfs/sw.lsst.eu/linux-x86_64/lsst_distrib/w_2022_36/conda/envs/lsst-scipipe-4.1.0/share/eups/Linux64/daf_butler/g3ee7dd65e6+24e5aa5155/python/lsst/daf/butler/cli/utils.py", "lineno": 1093, "funcName": "inner", "process": 116350, "processName": "MainProcess", "exc_info": "Traceback (most recent call last):\n\n  File \"/cvmfs/sw.lsst.eu/linux-x86_64/lsst_distrib/w_2022_36/conda/envs/lsst-scipipe-4.1.0/lib/python3.10/site-packages/sqlalchemy/engine/base.py\", line 3361, in _wrap_pool_connect\n    return fn()\n\n  File \"/cvmfs/sw.lsst.eu/linux-x86_64/lsst_distrib/w_2022_36/conda/envs/lsst-scipipe-4.1.0/lib/python3.10/site-packages/sqlalchemy/pool/base.py\", line 310, in connect\n    return _ConnectionFairy._checkout(self)\n\n  File \"/cvmfs/sw.lsst.eu/linux-x86_64/lsst_distrib/w_2022_36/conda/envs/lsst-scipipe-4.1.0/lib/python3.10/site-packages/sqlalchemy/pool/base.py\", line 868, in _checkout\n    fairy = _ConnectionRecord.checkout(pool)\n\n  File \"/cvmfs/sw.lsst.eu/linux-x86_64/lsst_distrib/w_2022_36/conda/envs/lsst-scipipe-4.1.0/lib/python3.10/site-packages/sqlalchemy/pool/base.py\", line 476, in checkout\n    rec = pool._do_get()\n\n  File \"/cvmfs/sw.lsst.eu/linux-x86_64/lsst_distrib/w_2022_36/conda/envs/lsst-scipipe-4.1.0/lib/python3.10/site-packages/sqlalchemy/pool/impl.py\", line 145, in _do_get\n    with util.safe_reraise():\n\n  File \"/cvmfs/sw.lsst.eu/linux-x86_64/lsst_distrib/w_2022_36/conda/envs/lsst-scipipe-4.1.0/lib/python3.10/site-packages/sqlalchemy/util/langhelpers.py\", line 70, in __exit__\n    compat.raise_(\n\n  File \"/cvmfs/sw.lsst.eu/linux-x86_64/lsst_distrib/w_2022_36/conda/envs/lsst-scipipe-4.1.0/lib/python3.10/site-packages/sqlalchemy/util/compat.py\", line 208, in raise_\n    raise exception\n\n  File \"/cvmfs/sw.lsst.eu/linux-x86_64/lsst_distrib/w_2022_36/conda/envs/lsst-scipipe-4.1.0/lib/python3.10/site-packages/sqlalchemy/pool/impl.py\", line 143, in _do_get\n    return self._create_connection()\n\n  File \"/cvmfs/sw.lsst.eu/linux-x86_64/lsst_distrib/w_2022_36/conda/envs/lsst-scipipe-4.1.0/lib/python3.10/site-packages/sqlalchemy/pool/base.py\", line 256, in _create_connection\n    return _ConnectionRecord(self)\n\n  File \"/cvmfs/sw.lsst.eu/linux-x86_64/lsst_distrib/w_2022_36/conda/envs/lsst-scipipe-4.1.0/lib/python3.10/site-packages/sqlalchemy/pool/base.py\", line 371, in __init__\n    self.__connect()\n\n  File \"/cvmfs/sw.lsst.eu/linux-x86_64/lsst_distrib/w_2022_36/conda/envs/lsst-scipipe-4.1.0/lib/python3.10/site-packages/sqlalchemy/pool/base.py\", line 679, in __connect\n    )._exec_w_sync_on_first_run(self.dbapi_connection, self)\n\n  File \"/cvmfs/sw.lsst.eu/linux-x86_64/lsst_distrib/w_2022_36/conda/envs/lsst-scipipe-4.1.0/lib/python3.10/site-packages/sqlalchemy/event/attr.py\", line 329, in _exec_w_sync_on_first_run\n    self(*args, **kw)\n\n  File \"/cvmfs/sw.lsst.eu/linux-x86_64/lsst_distrib/w_2022_36/conda/envs/lsst-scipipe-4.1.0/lib/python3.10/site-packages/sqlalchemy/event/attr.py\", line 343, in __call__\n    fn(*args, **kw)\n\n  File \"/cvmfs/sw.lsst.eu/linux-x86_64/lsst_distrib/w_2022_36/conda/envs/lsst-scipipe-4.1.0/lib/python3.10/site-packages/sqlalchemy/engine/create.py\", line 658, in on_connect\n    do_on_connect(dbapi_connection)\n\n  File \"/cvmfs/sw.lsst.eu/linux-x86_64/lsst_distrib/w_2022_36/conda/envs/lsst-scipipe-4.1.0/lib/python3.10/site-packages/sqlalchemy/dialects/postgresql/psycopg2.py\", line 950, in on_connect\n    fn(conn)\n\n  File \"/cvmfs/sw.lsst.eu/linux-x86_64/lsst_distrib/w_2022_36/conda/envs/lsst-scipipe-4.1.0/lib/python3.10/site-packages/sqlalchemy/dialects/postgresql/psycopg2.py\", line 923, in on_connect\n    hstore_oids = self._hstore_oids(conn)\n\n  File \"/cvmfs/sw.lsst.eu/linux-x86_64/lsst_distrib/w_2022_36/conda/envs/lsst-scipipe-4.1.0/lib/python3.10/site-packages/sqlalchemy/util/langhelpers.py\", line 1134, in oneshot\n    result = fn(self, *args, **kw)\n\n  File \"/cvmfs/sw.lsst.eu/linux-x86_64/lsst_distrib/w_2022_36/conda/envs/lsst-scipipe-4.1.0/lib/python3.10/site-packages/sqlalchemy/dialects/postgresql/psycopg2.py\", line 1007, in _hstore_oids\n    oids = extras.HstoreAdapter.get_oids(conn)\n\n  File \"/cvmfs/sw.lsst.eu/linux-x86_64/lsst_distrib/w_2022_36/conda/envs/lsst-scipipe-4.1.0/lib/python3.10/site-packages/psycopg2/extras.py\", line 911, in get_oids\n    curs.execute(f\"\"\"SELECT t.oid, {typarray}\n\npsycopg2.OperationalError: query_wait_timeout\nSSL connection has been closed unexpectedly\n\n\n\nThe above exception was the direct cause of the following exception:\n\n\nTraceback (most recent call last):\n\n  File \"/cvmfs/sw.lsst.eu/linux-x86_64/lsst_distrib/w_2022_36/conda/envs/lsst-scipipe-4.1.0/share/eups/Linux64/ctrl_mpexec/g5106228df7+1629eaad64/python/lsst/ctrl/mpexec/cli/cmd/commands.py\", line 140, in qgraph\n    script.qgraph(pipelineObj=pipeline, **kwargs, show=show)\n\n  File \"/cvmfs/sw.lsst.eu/linux-x86_64/lsst_distrib/w_2022_36/conda/envs/lsst-scipipe-4.1.0/share/eups/Linux64/ctrl_mpexec/g5106228df7+1629eaad64/python/lsst/ctrl/mpexec/cli/script/qgraph.py\", line 196, in qgraph\n    qgraph = f.makeGraph(pipelineObj, args)\n\n  File \"/cvmfs/sw.lsst.eu/linux-x86_64/lsst_distrib/w_2022_36/conda/envs/lsst-scipipe-4.1.0/share/eups/Linux64/ctrl_mpexec/g5106228df7+1629eaad64/python/lsst/ctrl/mpexec/cmdLineFwk.py\", line 525, in makeGraph\n    butler, collections, run = _ButlerFactory.makeButlerAndCollections(args)\n\n  File \"/cvmfs/sw.lsst.eu/linux-x86_64/lsst_distrib/w_2022_36/conda/envs/lsst-scipipe-4.1.0/share/eups/Linux64/ctrl_mpexec/g5106228df7+1629eaad64/python/lsst/ctrl/mpexec/cmdLineFwk.py\", line 347, in makeButlerAndCollections\n    butler, inputs, self = cls._makeReadParts(args)\n\n  File \"/cvmfs/sw.lsst.eu/linux-x86_64/lsst_distrib/w_2022_36/conda/envs/lsst-scipipe-4.1.0/share/eups/Linux64/ctrl_mpexec/g5106228df7+1629eaad64/python/lsst/ctrl/mpexec/cmdLineFwk.py\", line 282, in _makeReadParts\n    butler = Butler(args.butler_config, writeable=False)\n\n  File \"/cvmfs/sw.lsst.eu/linux-x86_64/lsst_distrib/w_2022_36/conda/envs/lsst-scipipe-4.1.0/share/eups/Linux64/daf_butler/g3ee7dd65e6+24e5aa5155/python/lsst/daf/butler/_butler.py\", line 281, in __init__\n    self.registry = Registry.fromConfig(\n\n  File \"/cvmfs/sw.lsst.eu/linux-x86_64/lsst_distrib/w_2022_36/conda/envs/lsst-scipipe-4.1.0/share/eups/Linux64/daf_butler/g3ee7dd65e6+24e5aa5155/python/lsst/daf/butler/registry/_registry.py\", line 230, in fromConfig\n    return registry_cls.fromConfig(config, butlerRoot, writeable, defaults)\n\n  File \"/cvmfs/sw.lsst.eu/linux-x86_64/lsst_distrib/w_2022_36/conda/envs/lsst-scipipe-4.1.0/share/eups/Linux64/daf_butler/g3ee7dd65e6+24e5aa5155/python/lsst/daf/butler/registries/sql.py\", line 188, in fromConfig\n    database = DatabaseClass.fromUri(\n\n  File \"/cvmfs/sw.lsst.eu/linux-x86_64/lsst_distrib/w_2022_36/conda/envs/lsst-scipipe-4.1.0/share/eups/Linux64/daf_butler/g3ee7dd65e6+24e5aa5155/python/lsst/daf/butler/registry/interfaces/_database.py\", line 366, in fromUri\n    return cls.fromEngine(\n\n  File \"/cvmfs/sw.lsst.eu/linux-x86_64/lsst_distrib/w_2022_36/conda/envs/lsst-scipipe-4.1.0/share/eups/Linux64/daf_butler/g3ee7dd65e6+24e5aa5155/python/lsst/daf/butler/registry/databases/postgresql.py\", line 110, in fromEngine\n    return cls(engine=engine, origin=origin, namespace=namespace, writeable=writeable)\n\n  File \"/cvmfs/sw.lsst.eu/linux-x86_64/lsst_distrib/w_2022_36/conda/envs/lsst-scipipe-4.1.0/share/eups/Linux64/daf_butler/g3ee7dd65e6+24e5aa5155/python/lsst/daf/butler/registry/databases/postgresql.py\", line 76, in __init__\n    with engine.connect() as connection:\n\n  File \"/cvmfs/sw.lsst.eu/linux-x86_64/lsst_distrib/w_2022_36/conda/envs/lsst-scipipe-4.1.0/lib/python3.10/site-packages/sqlalchemy/engine/base.py\", line 3315, in connect\n    return self._connection_cls(self, close_with_result=close_with_result)\n\n  File \"/cvmfs/sw.lsst.eu/linux-x86_64/lsst_distrib/w_2022_36/conda/envs/lsst-scipipe-4.1.0/lib/python3.10/site-packages/sqlalchemy/engine/base.py\", line 96, in __init__\n    else engine.raw_connection()\n\n  File \"/cvmfs/sw.lsst.eu/linux-x86_64/lsst_distrib/w_2022_36/conda/envs/lsst-scipipe-4.1.0/lib/python3.10/site-packages/sqlalchemy/engine/base.py\", line 3394, in raw_connection\n    return self._wrap_pool_connect(self.pool.connect, _connection)\n\n  File \"/cvmfs/sw.lsst.eu/linux-x86_64/lsst_distrib/w_2022_36/conda/envs/lsst-scipipe-4.1.0/lib/python3.10/site-packages/sqlalchemy/engine/base.py\", line 3364, in _wrap_pool_connect\n    Connection._handle_dbapi_exception_noconnection(\n\n  File \"/cvmfs/sw.lsst.eu/linux-x86_64/lsst_distrib/w_2022_36/conda/envs/lsst-scipipe-4.1.0/lib/python3.10/site-packages/sqlalchemy/engine/base.py\", line 2198, in _handle_dbapi_exception_noconnection\n    util.raise_(\n\n  File \"/cvmfs/sw.lsst.eu/linux-x86_64/lsst_distrib/w_2022_36/conda/envs/lsst-scipipe-4.1.0/lib/python3.10/site-packages/sqlalchemy/util/compat.py\", line 208, in raise_\n    raise exception\n\n  File \"/cvmfs/sw.lsst.eu/linux-x86_64/lsst_distrib/w_2022_36/conda/envs/lsst-scipipe-4.1.0/lib/python3.10/site-packages/sqlalchemy/engine/base.py\", line 3361, in _wrap_pool_connect\n    return fn()\n\n  File \"/cvmfs/sw.lsst.eu/linux-x86_64/lsst_distrib/w_2022_36/conda/envs/lsst-scipipe-4.1.0/lib/python3.10/site-packages/sqlalchemy/pool/base.py\", line 310, in connect\n    return _ConnectionFairy._checkout(self)\n\n  File \"/cvmfs/sw.lsst.eu/linux-x86_64/lsst_distrib/w_2022_36/conda/envs/lsst-scipipe-4.1.0/lib/python3.10/site-packages/sqlalchemy/pool/base.py\", line 868, in _checkout\n    fairy = _ConnectionRecord.checkout(pool)\n\n  File \"/cvmfs/sw.lsst.eu/linux-x86_64/lsst_distrib/w_2022_36/conda/envs/lsst-scipipe-4.1.0/lib/python3.10/site-packages/sqlalchemy/pool/base.py\", line 476, in checkout\n    rec = pool._do_get()\n\n  File \"/cvmfs/sw.lsst.eu/linux-x86_64/lsst_distrib/w_2022_36/conda/envs/lsst-scipipe-4.1.0/lib/python3.10/site-packages/sqlalchemy/pool/impl.py\", line 145, in _do_get\n    with util.safe_reraise():\n\n  File \"/cvmfs/sw.lsst.eu/linux-x86_64/lsst_distrib/w_2022_36/conda/envs/lsst-scipipe-4.1.0/lib/python3.10/site-packages/sqlalchemy/util/langhelpers.py\", line 70, in __exit__\n    compat.raise_(\n\n  File \"/cvmfs/sw.lsst.eu/linux-x86_64/lsst_distrib/w_2022_36/conda/envs/lsst-scipipe-4.1.0/lib/python3.10/site-packages/sqlalchemy/util/compat.py\", line 208, in raise_\n    raise exception\n\n  File \"/cvmfs/sw.lsst.eu/linux-x86_64/lsst_distrib/w_2022_36/conda/envs/lsst-scipipe-4.1.0/lib/python3.10/site-packages/sqlalchemy/pool/impl.py\", line 143, in _do_get\n    return self._create_connection()\n\n  File \"/cvmfs/sw.lsst.eu/linux-x86_64/lsst_distrib/w_2022_36/conda/envs/lsst-scipipe-4.1.0/lib/python3.10/site-packages/sqlalchemy/pool/base.py\", line 256, in _create_connection\n    return _ConnectionRecord(self)\n\n  File \"/cvmfs/sw.lsst.eu/linux-x86_64/lsst_distrib/w_2022_36/conda/envs/lsst-scipipe-4.1.0/lib/python3.10/site-packages/sqlalchemy/pool/base.py\", line 371, in __init__\n    self.__connect()\n\n  File \"/cvmfs/sw.lsst.eu/linux-x86_64/lsst_distrib/w_2022_36/conda/envs/lsst-scipipe-4.1.0/lib/python3.10/site-packages/sqlalchemy/pool/base.py\", line 679, in __connect\n    )._exec_w_sync_on_first_run(self.dbapi_connection, self)\n\n  File \"/cvmfs/sw.lsst.eu/linux-x86_64/lsst_distrib/w_2022_36/conda/envs/lsst-scipipe-4.1.0/lib/python3.10/site-packages/sqlalchemy/event/attr.py\", line 329, in _exec_w_sync_on_first_run\n    self(*args, **kw)\n\n  File \"/cvmfs/sw.lsst.eu/linux-x86_64/lsst_distrib/w_2022_36/conda/envs/lsst-scipipe-4.1.0/lib/python3.10/site-packages/sqlalchemy/event/attr.py\", line 343, in __call__\n    fn(*args, **kw)\n\n  File \"/cvmfs/sw.lsst.eu/linux-x86_64/lsst_distrib/w_2022_36/conda/envs/lsst-scipipe-4.1.0/lib/python3.10/site-packages/sqlalchemy/engine/create.py\", line 658, in on_connect\n    do_on_connect(dbapi_connection)\n\n  File \"/cvmfs/sw.lsst.eu/linux-x86_64/lsst_distrib/w_2022_36/conda/envs/lsst-scipipe-4.1.0/lib/python3.10/site-packages/sqlalchemy/dialects/postgresql/psycopg2.py\", line 950, in on_connect\n    fn(conn)\n\n  File \"/cvmfs/sw.lsst.eu/linux-x86_64/lsst_distrib/w_2022_36/conda/envs/lsst-scipipe-4.1.0/lib/python3.10/site-packages/sqlalchemy/dialects/postgresql/psycopg2.py\", line 923, in on_connect\n    hstore_oids = self._hstore_oids(conn)\n\n  File \"/cvmfs/sw.lsst.eu/linux-x86_64/lsst_distrib/w_2022_36/conda/envs/lsst-scipipe-4.1.0/lib/python3.10/site-packages/sqlalchemy/util/langhelpers.py\", line 1134, in oneshot\n    result = fn(self, *args, **kw)\n\n  File \"/cvmfs/sw.lsst.eu/linux-x86_64/lsst_distrib/w_2022_36/conda/envs/lsst-scipipe-4.1.0/lib/python3.10/site-packages/sqlalchemy/dialects/postgresql/psycopg2.py\", line 1007, in _hstore_oids\n    oids = extras.HstoreAdapter.get_oids(conn)\n\n  File \"/cvmfs/sw.lsst.eu/linux-x86_64/lsst_distrib/w_2022_36/conda/envs/lsst-scipipe-4.1.0/lib/python3.10/site-packages/psycopg2/extras.py\", line 911, in get_oids\n    curs.execute(f\"\"\"SELECT t.oid, {typarray}\n\nsqlalchemy.exc.OperationalError: (psycopg2.OperationalError) query_wait_timeout\nSSL connection has been closed unexpectedly\n\n(Background on this error at: https://sqlalche.me/e/14/e3q8)\n", "MDC": {}}
{"name": "py.warnings", "asctime": "2022-09-06T19:49:51.194333+00:00", "message": "/cvmfs/sw.lsst.eu/linux-x86_64/lsst_distrib/w_2022_36/conda/envs/lsst-scipipe-4.1.0/share/eups/Linux64/pex_config/g71c1dbb2b5+34f28eb435/python/lsst/pex/config/configurableField.py:79: FutureWarning: Call to deprecated class LoadIndexedReferenceObjectsConfig. (This config is no longer used; it will be removed after v25. Please use LoadReferenceObjectsConfig instead.) -- Deprecated since version v25.0.\n  value = self._ConfigClass(__name=name, __at=at, __label=label, **storage)\n", "levelno": 30, "levelname": "WARNING", "filename": "warnings.py", "pathname": "/cvmfs/sw.lsst.eu/linux-x86_64/lsst_distrib/w_2022_36/conda/envs/lsst-scipipe-4.1.0/lib/python3.10/warnings.py", "lineno": 109, "funcName": "_showwarnmsg", "process": 119811, "processName": "MainProcess", "MDC": {}}
{"name": "py.warnings", "asctime": "2022-09-06T19:49:51.203011+00:00", "message": "/cvmfs/sw.lsst.eu/linux-x86_64/lsst_distrib/w_2022_36/conda/envs/lsst-scipipe-4.1.0/share/eups/Linux64/pex_config/g71c1dbb2b5+34f28eb435/python/lsst/pex/config/configurableField.py:359: FutureWarning: Call to deprecated class LoadIndexedReferenceObjectsConfig. (This config is no longer used; it will be removed after v25. Please use LoadReferenceObjectsConfig instead.) -- Deprecated since version v25.0.\n  value = oldValue.ConfigClass()\n", "levelno": 30, "levelname": "WARNING", "filename": "warnings.py", "pathname": "/cvmfs/sw.lsst.eu/linux-x86_64/lsst_distrib/w_2022_36/conda/envs/lsst-scipipe-4.1.0/lib/python3.10/warnings.py", "lineno": 109, "funcName": "_showwarnmsg", "process": 119811, "processName": "MainProcess", "MDC": {}}
{"name": "lsst.daf.butler._butler", "asctime": "2022-09-06T22:09:25.154240+00:00", "message": "Failed to instantiate Butler from config file:///sdf/group/rubin/repo/main_20220411/butler.yaml.", "levelno": 40, "levelname": "ERROR", "filename": "_butler.py", "pathname": "/cvmfs/sw.lsst.eu/linux-x86_64/lsst_distrib/w_2022_36/conda/envs/lsst-scipipe-4.1.0/share/eups/Linux64/daf_butler/g3ee7dd65e6+24e5aa5155/python/lsst/daf/butler/_butler.py", "lineno": 295, "funcName": "__init__", "process": 2863, "processName": "MainProcess", "MDC": {}}
{"name": "lsst.daf.butler.cli.utils", "asctime": "2022-09-06T22:09:25.173234+00:00", "message": "Caught an exception, details are in traceback:", "levelno": 40, "levelname": "ERROR", "filename": "utils.py", "pathname": "/cvmfs/sw.lsst.eu/linux-x86_64/lsst_distrib/w_2022_36/conda/envs/lsst-scipipe-4.1.0/share/eups/Linux64/daf_butler/g3ee7dd65e6+24e5aa5155/python/lsst/daf/butler/cli/utils.py", "lineno": 1093, "funcName": "inner", "process": 2863, "processName": "MainProcess", "exc_info": "Traceback (most recent call last):\n\n  File \"/cvmfs/sw.lsst.eu/linux-x86_64/lsst_distrib/w_2022_36/conda/envs/lsst-scipipe-4.1.0/lib/python3.10/site-packages/sqlalchemy/engine/base.py\", line 3361, in _wrap_pool_connect\n    return fn()\n\n  File \"/cvmfs/sw.lsst.eu/linux-x86_64/lsst_distrib/w_2022_36/conda/envs/lsst-scipipe-4.1.0/lib/python3.10/site-packages/sqlalchemy/pool/base.py\", line 310, in connect\n    return _ConnectionFairy._checkout(self)\n\n  File \"/cvmfs/sw.lsst.eu/linux-x86_64/lsst_distrib/w_2022_36/conda/envs/lsst-scipipe-4.1.0/lib/python3.10/site-packages/sqlalchemy/pool/base.py\", line 868, in _checkout\n    fairy = _ConnectionRecord.checkout(pool)\n\n  File \"/cvmfs/sw.lsst.eu/linux-x86_64/lsst_distrib/w_2022_36/conda/envs/lsst-scipipe-4.1.0/lib/python3.10/site-packages/sqlalchemy/pool/base.py\", line 476, in checkout\n    rec = pool._do_get()\n\n  File \"/cvmfs/sw.lsst.eu/linux-x86_64/lsst_distrib/w_2022_36/conda/envs/lsst-scipipe-4.1.0/lib/python3.10/site-packages/sqlalchemy/pool/impl.py\", line 145, in _do_get\n    with util.safe_reraise():\n\n  File \"/cvmfs/sw.lsst.eu/linux-x86_64/lsst_distrib/w_2022_36/conda/envs/lsst-scipipe-4.1.0/lib/python3.10/site-packages/sqlalchemy/util/langhelpers.py\", line 70, in __exit__\n    compat.raise_(\n\n  File \"/cvmfs/sw.lsst.eu/linux-x86_64/lsst_distrib/w_2022_36/conda/envs/lsst-scipipe-4.1.0/lib/python3.10/site-packages/sqlalchemy/util/compat.py\", line 208, in raise_\n    raise exception\n\n  File \"/cvmfs/sw.lsst.eu/linux-x86_64/lsst_distrib/w_2022_36/conda/envs/lsst-scipipe-4.1.0/lib/python3.10/site-packages/sqlalchemy/pool/impl.py\", line 143, in _do_get\n    return self._create_connection()\n\n  File \"/cvmfs/sw.lsst.eu/linux-x86_64/lsst_distrib/w_2022_36/conda/envs/lsst-scipipe-4.1.0/lib/python3.10/site-packages/sqlalchemy/pool/base.py\", line 256, in _create_connection\n    return _ConnectionRecord(self)\n\n  File \"/cvmfs/sw.lsst.eu/linux-x86_64/lsst_distrib/w_2022_36/conda/envs/lsst-scipipe-4.1.0/lib/python3.10/site-packages/sqlalchemy/pool/base.py\", line 371, in __init__\n    self.__connect()\n\n  File \"/cvmfs/sw.lsst.eu/linux-x86_64/lsst_distrib/w_2022_36/conda/envs/lsst-scipipe-4.1.0/lib/python3.10/site-packages/sqlalchemy/pool/base.py\", line 679, in __connect\n    )._exec_w_sync_on_first_run(self.dbapi_connection, self)\n\n  File \"/cvmfs/sw.lsst.eu/linux-x86_64/lsst_distrib/w_2022_36/conda/envs/lsst-scipipe-4.1.0/lib/python3.10/site-packages/sqlalchemy/event/attr.py\", line 329, in _exec_w_sync_on_first_run\n    self(*args, **kw)\n\n  File \"/cvmfs/sw.lsst.eu/linux-x86_64/lsst_distrib/w_2022_36/conda/envs/lsst-scipipe-4.1.0/lib/python3.10/site-packages/sqlalchemy/event/attr.py\", line 343, in __call__\n    fn(*args, **kw)\n\n  File \"/cvmfs/sw.lsst.eu/linux-x86_64/lsst_distrib/w_2022_36/conda/envs/lsst-scipipe-4.1.0/lib/python3.10/site-packages/sqlalchemy/engine/create.py\", line 658, in on_connect\n    do_on_connect(dbapi_connection)\n\n  File \"/cvmfs/sw.lsst.eu/linux-x86_64/lsst_distrib/w_2022_36/conda/envs/lsst-scipipe-4.1.0/lib/python3.10/site-packages/sqlalchemy/dialects/postgresql/psycopg2.py\", line 950, in on_connect\n    fn(conn)\n\n  File \"/cvmfs/sw.lsst.eu/linux-x86_64/lsst_distrib/w_2022_36/conda/envs/lsst-scipipe-4.1.0/lib/python3.10/site-packages/sqlalchemy/dialects/postgresql/psycopg2.py\", line 923, in on_connect\n    hstore_oids = self._hstore_oids(conn)\n\n  File \"/cvmfs/sw.lsst.eu/linux-x86_64/lsst_distrib/w_2022_36/conda/envs/lsst-scipipe-4.1.0/lib/python3.10/site-packages/sqlalchemy/util/langhelpers.py\", line 1134, in oneshot\n    result = fn(self, *args, **kw)\n\n  File \"/cvmfs/sw.lsst.eu/linux-x86_64/lsst_distrib/w_2022_36/conda/envs/lsst-scipipe-4.1.0/lib/python3.10/site-packages/sqlalchemy/dialects/postgresql/psycopg2.py\", line 1007, in _hstore_oids\n    oids = extras.HstoreAdapter.get_oids(conn)\n\n  File \"/cvmfs/sw.lsst.eu/linux-x86_64/lsst_distrib/w_2022_36/conda/envs/lsst-scipipe-4.1.0/lib/python3.10/site-packages/psycopg2/extras.py\", line 911, in get_oids\n    curs.execute(f\"\"\"SELECT t.oid, {typarray}\n\npsycopg2.OperationalError: query_wait_timeout\nSSL connection has been closed unexpectedly\n\n\n\nThe above exception was the direct cause of the following exception:\n\n\nTraceback (most recent call last):\n\n  File \"/cvmfs/sw.lsst.eu/linux-x86_64/lsst_distrib/w_2022_36/conda/envs/lsst-scipipe-4.1.0/share/eups/Linux64/ctrl_mpexec/g5106228df7+1629eaad64/python/lsst/ctrl/mpexec/cli/cmd/commands.py\", line 140, in qgraph\n    script.qgraph(pipelineObj=pipeline, **kwargs, show=show)\n\n  File \"/cvmfs/sw.lsst.eu/linux-x86_64/lsst_distrib/w_2022_36/conda/envs/lsst-scipipe-4.1.0/share/eups/Linux64/ctrl_mpexec/g5106228df7+1629eaad64/python/lsst/ctrl/mpexec/cli/script/qgraph.py\", line 196, in qgraph\n    qgraph = f.makeGraph(pipelineObj, args)\n\n  File \"/cvmfs/sw.lsst.eu/linux-x86_64/lsst_distrib/w_2022_36/conda/envs/lsst-scipipe-4.1.0/share/eups/Linux64/ctrl_mpexec/g5106228df7+1629eaad64/python/lsst/ctrl/mpexec/cmdLineFwk.py\", line 525, in makeGraph\n    butler, collections, run = _ButlerFactory.makeButlerAndCollections(args)\n\n  File \"/cvmfs/sw.lsst.eu/linux-x86_64/lsst_distrib/w_2022_36/conda/envs/lsst-scipipe-4.1.0/share/eups/Linux64/ctrl_mpexec/g5106228df7+1629eaad64/python/lsst/ctrl/mpexec/cmdLineFwk.py\", line 347, in makeButlerAndCollections\n    butler, inputs, self = cls._makeReadParts(args)\n\n  File \"/cvmfs/sw.lsst.eu/linux-x86_64/lsst_distrib/w_2022_36/conda/envs/lsst-scipipe-4.1.0/share/eups/Linux64/ctrl_mpexec/g5106228df7+1629eaad64/python/lsst/ctrl/mpexec/cmdLineFwk.py\", line 282, in _makeReadParts\n    butler = Butler(args.butler_config, writeable=False)\n\n  File \"/cvmfs/sw.lsst.eu/linux-x86_64/lsst_distrib/w_2022_36/conda/envs/lsst-scipipe-4.1.0/share/eups/Linux64/daf_butler/g3ee7dd65e6+24e5aa5155/python/lsst/daf/butler/_butler.py\", line 281, in __init__\n    self.registry = Registry.fromConfig(\n\n  File \"/cvmfs/sw.lsst.eu/linux-x86_64/lsst_distrib/w_2022_36/conda/envs/lsst-scipipe-4.1.0/share/eups/Linux64/daf_butler/g3ee7dd65e6+24e5aa5155/python/lsst/daf/butler/registry/_registry.py\", line 230, in fromConfig\n    return registry_cls.fromConfig(config, butlerRoot, writeable, defaults)\n\n  File \"/cvmfs/sw.lsst.eu/linux-x86_64/lsst_distrib/w_2022_36/conda/envs/lsst-scipipe-4.1.0/share/eups/Linux64/daf_butler/g3ee7dd65e6+24e5aa5155/python/lsst/daf/butler/registries/sql.py\", line 188, in fromConfig\n    database = DatabaseClass.fromUri(\n\n  File \"/cvmfs/sw.lsst.eu/linux-x86_64/lsst_distrib/w_2022_36/conda/envs/lsst-scipipe-4.1.0/share/eups/Linux64/daf_butler/g3ee7dd65e6+24e5aa5155/python/lsst/daf/butler/registry/interfaces/_database.py\", line 366, in fromUri\n    return cls.fromEngine(\n\n  File \"/cvmfs/sw.lsst.eu/linux-x86_64/lsst_distrib/w_2022_36/conda/envs/lsst-scipipe-4.1.0/share/eups/Linux64/daf_butler/g3ee7dd65e6+24e5aa5155/python/lsst/daf/butler/registry/databases/postgresql.py\", line 110, in fromEngine\n    return cls(engine=engine, origin=origin, namespace=namespace, writeable=writeable)\n\n  File \"/cvmfs/sw.lsst.eu/linux-x86_64/lsst_distrib/w_2022_36/conda/envs/lsst-scipipe-4.1.0/share/eups/Linux64/daf_butler/g3ee7dd65e6+24e5aa5155/python/lsst/daf/butler/registry/databases/postgresql.py\", line 76, in __init__\n    with engine.connect() as connection:\n\n  File \"/cvmfs/sw.lsst.eu/linux-x86_64/lsst_distrib/w_2022_36/conda/envs/lsst-scipipe-4.1.0/lib/python3.10/site-packages/sqlalchemy/engine/base.py\", line 3315, in connect\n    return self._connection_cls(self, close_with_result=close_with_result)\n\n  File \"/cvmfs/sw.lsst.eu/linux-x86_64/lsst_distrib/w_2022_36/conda/envs/lsst-scipipe-4.1.0/lib/python3.10/site-packages/sqlalchemy/engine/base.py\", line 96, in __init__\n    else engine.raw_connection()\n\n  File \"/cvmfs/sw.lsst.eu/linux-x86_64/lsst_distrib/w_2022_36/conda/envs/lsst-scipipe-4.1.0/lib/python3.10/site-packages/sqlalchemy/engine/base.py\", line 3394, in raw_connection\n    return self._wrap_pool_connect(self.pool.connect, _connection)\n\n  File \"/cvmfs/sw.lsst.eu/linux-x86_64/lsst_distrib/w_2022_36/conda/envs/lsst-scipipe-4.1.0/lib/python3.10/site-packages/sqlalchemy/engine/base.py\", line 3364, in _wrap_pool_connect\n    Connection._handle_dbapi_exception_noconnection(\n\n  File \"/cvmfs/sw.lsst.eu/linux-x86_64/lsst_distrib/w_2022_36/conda/envs/lsst-scipipe-4.1.0/lib/python3.10/site-packages/sqlalchemy/engine/base.py\", line 2198, in _handle_dbapi_exception_noconnection\n    util.raise_(\n\n  File \"/cvmfs/sw.lsst.eu/linux-x86_64/lsst_distrib/w_2022_36/conda/envs/lsst-scipipe-4.1.0/lib/python3.10/site-packages/sqlalchemy/util/compat.py\", line 208, in raise_\n    raise exception\n\n  File \"/cvmfs/sw.lsst.eu/linux-x86_64/lsst_distrib/w_2022_36/conda/envs/lsst-scipipe-4.1.0/lib/python3.10/site-packages/sqlalchemy/engine/base.py\", line 3361, in _wrap_pool_connect\n    return fn()\n\n  File \"/cvmfs/sw.lsst.eu/linux-x86_64/lsst_distrib/w_2022_36/conda/envs/lsst-scipipe-4.1.0/lib/python3.10/site-packages/sqlalchemy/pool/base.py\", line 310, in connect\n    return _ConnectionFairy._checkout(self)\n\n  File \"/cvmfs/sw.lsst.eu/linux-x86_64/lsst_distrib/w_2022_36/conda/envs/lsst-scipipe-4.1.0/lib/python3.10/site-packages/sqlalchemy/pool/base.py\", line 868, in _checkout\n    fairy = _ConnectionRecord.checkout(pool)\n\n  File \"/cvmfs/sw.lsst.eu/linux-x86_64/lsst_distrib/w_2022_36/conda/envs/lsst-scipipe-4.1.0/lib/python3.10/site-packages/sqlalchemy/pool/base.py\", line 476, in checkout\n    rec = pool._do_get()\n\n  File \"/cvmfs/sw.lsst.eu/linux-x86_64/lsst_distrib/w_2022_36/conda/envs/lsst-scipipe-4.1.0/lib/python3.10/site-packages/sqlalchemy/pool/impl.py\", line 145, in _do_get\n    with util.safe_reraise():\n\n  File \"/cvmfs/sw.lsst.eu/linux-x86_64/lsst_distrib/w_2022_36/conda/envs/lsst-scipipe-4.1.0/lib/python3.10/site-packages/sqlalchemy/util/langhelpers.py\", line 70, in __exit__\n    compat.raise_(\n\n  File \"/cvmfs/sw.lsst.eu/linux-x86_64/lsst_distrib/w_2022_36/conda/envs/lsst-scipipe-4.1.0/lib/python3.10/site-packages/sqlalchemy/util/compat.py\", line 208, in raise_\n    raise exception\n\n  File \"/cvmfs/sw.lsst.eu/linux-x86_64/lsst_distrib/w_2022_36/conda/envs/lsst-scipipe-4.1.0/lib/python3.10/site-packages/sqlalchemy/pool/impl.py\", line 143, in _do_get\n    return self._create_connection()\n\n  File \"/cvmfs/sw.lsst.eu/linux-x86_64/lsst_distrib/w_2022_36/conda/envs/lsst-scipipe-4.1.0/lib/python3.10/site-packages/sqlalchemy/pool/base.py\", line 256, in _create_connection\n    return _ConnectionRecord(self)\n\n  File \"/cvmfs/sw.lsst.eu/linux-x86_64/lsst_distrib/w_2022_36/conda/envs/lsst-scipipe-4.1.0/lib/python3.10/site-packages/sqlalchemy/pool/base.py\", line 371, in __init__\n    self.__connect()\n\n  File \"/cvmfs/sw.lsst.eu/linux-x86_64/lsst_distrib/w_2022_36/conda/envs/lsst-scipipe-4.1.0/lib/python3.10/site-packages/sqlalchemy/pool/base.py\", line 679, in __connect\n    )._exec_w_sync_on_first_run(self.dbapi_connection, self)\n\n  File \"/cvmfs/sw.lsst.eu/linux-x86_64/lsst_distrib/w_2022_36/conda/envs/lsst-scipipe-4.1.0/lib/python3.10/site-packages/sqlalchemy/event/attr.py\", line 329, in _exec_w_sync_on_first_run\n    self(*args, **kw)\n\n  File \"/cvmfs/sw.lsst.eu/linux-x86_64/lsst_distrib/w_2022_36/conda/envs/lsst-scipipe-4.1.0/lib/python3.10/site-packages/sqlalchemy/event/attr.py\", line 343, in __call__\n    fn(*args, **kw)\n\n  File \"/cvmfs/sw.lsst.eu/linux-x86_64/lsst_distrib/w_2022_36/conda/envs/lsst-scipipe-4.1.0/lib/python3.10/site-packages/sqlalchemy/engine/create.py\", line 658, in on_connect\n    do_on_connect(dbapi_connection)\n\n  File \"/cvmfs/sw.lsst.eu/linux-x86_64/lsst_distrib/w_2022_36/conda/envs/lsst-scipipe-4.1.0/lib/python3.10/site-packages/sqlalchemy/dialects/postgresql/psycopg2.py\", line 950, in on_connect\n    fn(conn)\n\n  File \"/cvmfs/sw.lsst.eu/linux-x86_64/lsst_distrib/w_2022_36/conda/envs/lsst-scipipe-4.1.0/lib/python3.10/site-packages/sqlalchemy/dialects/postgresql/psycopg2.py\", line 923, in on_connect\n    hstore_oids = self._hstore_oids(conn)\n\n  File \"/cvmfs/sw.lsst.eu/linux-x86_64/lsst_distrib/w_2022_36/conda/envs/lsst-scipipe-4.1.0/lib/python3.10/site-packages/sqlalchemy/util/langhelpers.py\", line 1134, in oneshot\n    result = fn(self, *args, **kw)\n\n  File \"/cvmfs/sw.lsst.eu/linux-x86_64/lsst_distrib/w_2022_36/conda/envs/lsst-scipipe-4.1.0/lib/python3.10/site-packages/sqlalchemy/dialects/postgresql/psycopg2.py\", line 1007, in _hstore_oids\n    oids = extras.HstoreAdapter.get_oids(conn)\n\n  File \"/cvmfs/sw.lsst.eu/linux-x86_64/lsst_distrib/w_2022_36/conda/envs/lsst-scipipe-4.1.0/lib/python3.10/site-packages/psycopg2/extras.py\", line 911, in get_oids\n    curs.execute(f\"\"\"SELECT t.oid, {typarray}\n\nsqlalchemy.exc.OperationalError: (psycopg2.OperationalError) query_wait_timeout\nSSL connection has been closed unexpectedly\n\n(Background on this error at: https://sqlalche.me/e/14/e3q8)\n", "MDC": {}}
{"name": "lsst.daf.butler._butler", "asctime": "2022-09-06T22:16:49.627154+00:00", "message": "Failed to instantiate Butler from config file:///sdf/group/rubin/repo/main_20220411/butler.yaml.", "levelno": 40, "levelname": "ERROR", "filename": "_butler.py", "pathname": "/cvmfs/sw.lsst.eu/linux-x86_64/lsst_distrib/w_2022_36/conda/envs/lsst-scipipe-4.1.0/share/eups/Linux64/daf_butler/g3ee7dd65e6+24e5aa5155/python/lsst/daf/butler/_butler.py", "lineno": 295, "funcName": "__init__", "process": 4645, "processName": "MainProcess", "MDC": {}}
{"name": "lsst.daf.butler.cli.utils", "asctime": "2022-09-06T22:16:49.628733+00:00", "message": "Caught an exception, details are in traceback:", "levelno": 40, "levelname": "ERROR", "filename": "utils.py", "pathname": "/cvmfs/sw.lsst.eu/linux-x86_64/lsst_distrib/w_2022_36/conda/envs/lsst-scipipe-4.1.0/share/eups/Linux64/daf_butler/g3ee7dd65e6+24e5aa5155/python/lsst/daf/butler/cli/utils.py", "lineno": 1093, "funcName": "inner", "process": 4645, "processName": "MainProcess", "exc_info": "Traceback (most recent call last):\n\n  File \"/cvmfs/sw.lsst.eu/linux-x86_64/lsst_distrib/w_2022_36/conda/envs/lsst-scipipe-4.1.0/lib/python3.10/site-packages/sqlalchemy/engine/base.py\", line 3361, in _wrap_pool_connect\n    return fn()\n\n  File \"/cvmfs/sw.lsst.eu/linux-x86_64/lsst_distrib/w_2022_36/conda/envs/lsst-scipipe-4.1.0/lib/python3.10/site-packages/sqlalchemy/pool/base.py\", line 310, in connect\n    return _ConnectionFairy._checkout(self)\n\n  File \"/cvmfs/sw.lsst.eu/linux-x86_64/lsst_distrib/w_2022_36/conda/envs/lsst-scipipe-4.1.0/lib/python3.10/site-packages/sqlalchemy/pool/base.py\", line 868, in _checkout\n    fairy = _ConnectionRecord.checkout(pool)\n\n  File \"/cvmfs/sw.lsst.eu/linux-x86_64/lsst_distrib/w_2022_36/conda/envs/lsst-scipipe-4.1.0/lib/python3.10/site-packages/sqlalchemy/pool/base.py\", line 476, in checkout\n    rec = pool._do_get()\n\n  File \"/cvmfs/sw.lsst.eu/linux-x86_64/lsst_distrib/w_2022_36/conda/envs/lsst-scipipe-4.1.0/lib/python3.10/site-packages/sqlalchemy/pool/impl.py\", line 145, in _do_get\n    with util.safe_reraise():\n\n  File \"/cvmfs/sw.lsst.eu/linux-x86_64/lsst_distrib/w_2022_36/conda/envs/lsst-scipipe-4.1.0/lib/python3.10/site-packages/sqlalchemy/util/langhelpers.py\", line 70, in __exit__\n    compat.raise_(\n\n  File \"/cvmfs/sw.lsst.eu/linux-x86_64/lsst_distrib/w_2022_36/conda/envs/lsst-scipipe-4.1.0/lib/python3.10/site-packages/sqlalchemy/util/compat.py\", line 208, in raise_\n    raise exception\n\n  File \"/cvmfs/sw.lsst.eu/linux-x86_64/lsst_distrib/w_2022_36/conda/envs/lsst-scipipe-4.1.0/lib/python3.10/site-packages/sqlalchemy/pool/impl.py\", line 143, in _do_get\n    return self._create_connection()\n\n  File \"/cvmfs/sw.lsst.eu/linux-x86_64/lsst_distrib/w_2022_36/conda/envs/lsst-scipipe-4.1.0/lib/python3.10/site-packages/sqlalchemy/pool/base.py\", line 256, in _create_connection\n    return _ConnectionRecord(self)\n\n  File \"/cvmfs/sw.lsst.eu/linux-x86_64/lsst_distrib/w_2022_36/conda/envs/lsst-scipipe-4.1.0/lib/python3.10/site-packages/sqlalchemy/pool/base.py\", line 371, in __init__\n    self.__connect()\n\n  File \"/cvmfs/sw.lsst.eu/linux-x86_64/lsst_distrib/w_2022_36/conda/envs/lsst-scipipe-4.1.0/lib/python3.10/site-packages/sqlalchemy/pool/base.py\", line 679, in __connect\n    )._exec_w_sync_on_first_run(self.dbapi_connection, self)\n\n  File \"/cvmfs/sw.lsst.eu/linux-x86_64/lsst_distrib/w_2022_36/conda/envs/lsst-scipipe-4.1.0/lib/python3.10/site-packages/sqlalchemy/event/attr.py\", line 329, in _exec_w_sync_on_first_run\n    self(*args, **kw)\n\n  File \"/cvmfs/sw.lsst.eu/linux-x86_64/lsst_distrib/w_2022_36/conda/envs/lsst-scipipe-4.1.0/lib/python3.10/site-packages/sqlalchemy/event/attr.py\", line 343, in __call__\n    fn(*args, **kw)\n\n  File \"/cvmfs/sw.lsst.eu/linux-x86_64/lsst_distrib/w_2022_36/conda/envs/lsst-scipipe-4.1.0/lib/python3.10/site-packages/sqlalchemy/engine/create.py\", line 658, in on_connect\n    do_on_connect(dbapi_connection)\n\n  File \"/cvmfs/sw.lsst.eu/linux-x86_64/lsst_distrib/w_2022_36/conda/envs/lsst-scipipe-4.1.0/lib/python3.10/site-packages/sqlalchemy/dialects/postgresql/psycopg2.py\", line 950, in on_connect\n    fn(conn)\n\n  File \"/cvmfs/sw.lsst.eu/linux-x86_64/lsst_distrib/w_2022_36/conda/envs/lsst-scipipe-4.1.0/lib/python3.10/site-packages/sqlalchemy/dialects/postgresql/psycopg2.py\", line 923, in on_connect\n    hstore_oids = self._hstore_oids(conn)\n\n  File \"/cvmfs/sw.lsst.eu/linux-x86_64/lsst_distrib/w_2022_36/conda/envs/lsst-scipipe-4.1.0/lib/python3.10/site-packages/sqlalchemy/util/langhelpers.py\", line 1134, in oneshot\n    result = fn(self, *args, **kw)\n\n  File \"/cvmfs/sw.lsst.eu/linux-x86_64/lsst_distrib/w_2022_36/conda/envs/lsst-scipipe-4.1.0/lib/python3.10/site-packages/sqlalchemy/dialects/postgresql/psycopg2.py\", line 1007, in _hstore_oids\n    oids = extras.HstoreAdapter.get_oids(conn)\n\n  File \"/cvmfs/sw.lsst.eu/linux-x86_64/lsst_distrib/w_2022_36/conda/envs/lsst-scipipe-4.1.0/lib/python3.10/site-packages/psycopg2/extras.py\", line 911, in get_oids\n    curs.execute(f\"\"\"SELECT t.oid, {typarray}\n\npsycopg2.OperationalError: query_wait_timeout\nSSL connection has been closed unexpectedly\n\n\n\nThe above exception was the direct cause of the following exception:\n\n\nTraceback (most recent call last):\n\n  File \"/cvmfs/sw.lsst.eu/linux-x86_64/lsst_distrib/w_2022_36/conda/envs/lsst-scipipe-4.1.0/share/eups/Linux64/ctrl_mpexec/g5106228df7+1629eaad64/python/lsst/ctrl/mpexec/cli/cmd/commands.py\", line 140, in qgraph\n    script.qgraph(pipelineObj=pipeline, **kwargs, show=show)\n\n  File \"/cvmfs/sw.lsst.eu/linux-x86_64/lsst_distrib/w_2022_36/conda/envs/lsst-scipipe-4.1.0/share/eups/Linux64/ctrl_mpexec/g5106228df7+1629eaad64/python/lsst/ctrl/mpexec/cli/script/qgraph.py\", line 196, in qgraph\n    qgraph = f.makeGraph(pipelineObj, args)\n\n  File \"/cvmfs/sw.lsst.eu/linux-x86_64/lsst_distrib/w_2022_36/conda/envs/lsst-scipipe-4.1.0/share/eups/Linux64/ctrl_mpexec/g5106228df7+1629eaad64/python/lsst/ctrl/mpexec/cmdLineFwk.py\", line 525, in makeGraph\n    butler, collections, run = _ButlerFactory.makeButlerAndCollections(args)\n\n  File \"/cvmfs/sw.lsst.eu/linux-x86_64/lsst_distrib/w_2022_36/conda/envs/lsst-scipipe-4.1.0/share/eups/Linux64/ctrl_mpexec/g5106228df7+1629eaad64/python/lsst/ctrl/mpexec/cmdLineFwk.py\", line 347, in makeButlerAndCollections\n    butler, inputs, self = cls._makeReadParts(args)\n\n  File \"/cvmfs/sw.lsst.eu/linux-x86_64/lsst_distrib/w_2022_36/conda/envs/lsst-scipipe-4.1.0/share/eups/Linux64/ctrl_mpexec/g5106228df7+1629eaad64/python/lsst/ctrl/mpexec/cmdLineFwk.py\", line 282, in _makeReadParts\n    butler = Butler(args.butler_config, writeable=False)\n\n  File \"/cvmfs/sw.lsst.eu/linux-x86_64/lsst_distrib/w_2022_36/conda/envs/lsst-scipipe-4.1.0/share/eups/Linux64/daf_butler/g3ee7dd65e6+24e5aa5155/python/lsst/daf/butler/_butler.py\", line 281, in __init__\n    self.registry = Registry.fromConfig(\n\n  File \"/cvmfs/sw.lsst.eu/linux-x86_64/lsst_distrib/w_2022_36/conda/envs/lsst-scipipe-4.1.0/share/eups/Linux64/daf_butler/g3ee7dd65e6+24e5aa5155/python/lsst/daf/butler/registry/_registry.py\", line 230, in fromConfig\n    return registry_cls.fromConfig(config, butlerRoot, writeable, defaults)\n\n  File \"/cvmfs/sw.lsst.eu/linux-x86_64/lsst_distrib/w_2022_36/conda/envs/lsst-scipipe-4.1.0/share/eups/Linux64/daf_butler/g3ee7dd65e6+24e5aa5155/python/lsst/daf/butler/registries/sql.py\", line 188, in fromConfig\n    database = DatabaseClass.fromUri(\n\n  File \"/cvmfs/sw.lsst.eu/linux-x86_64/lsst_distrib/w_2022_36/conda/envs/lsst-scipipe-4.1.0/share/eups/Linux64/daf_butler/g3ee7dd65e6+24e5aa5155/python/lsst/daf/butler/registry/interfaces/_database.py\", line 366, in fromUri\n    return cls.fromEngine(\n\n  File \"/cvmfs/sw.lsst.eu/linux-x86_64/lsst_distrib/w_2022_36/conda/envs/lsst-scipipe-4.1.0/share/eups/Linux64/daf_butler/g3ee7dd65e6+24e5aa5155/python/lsst/daf/butler/registry/databases/postgresql.py\", line 110, in fromEngine\n    return cls(engine=engine, origin=origin, namespace=namespace, writeable=writeable)\n\n  File \"/cvmfs/sw.lsst.eu/linux-x86_64/lsst_distrib/w_2022_36/conda/envs/lsst-scipipe-4.1.0/share/eups/Linux64/daf_butler/g3ee7dd65e6+24e5aa5155/python/lsst/daf/butler/registry/databases/postgresql.py\", line 76, in __init__\n    with engine.connect() as connection:\n\n  File \"/cvmfs/sw.lsst.eu/linux-x86_64/lsst_distrib/w_2022_36/conda/envs/lsst-scipipe-4.1.0/lib/python3.10/site-packages/sqlalchemy/engine/base.py\", line 3315, in connect\n    return self._connection_cls(self, close_with_result=close_with_result)\n\n  File \"/cvmfs/sw.lsst.eu/linux-x86_64/lsst_distrib/w_2022_36/conda/envs/lsst-scipipe-4.1.0/lib/python3.10/site-packages/sqlalchemy/engine/base.py\", line 96, in __init__\n    else engine.raw_connection()\n\n  File \"/cvmfs/sw.lsst.eu/linux-x86_64/lsst_distrib/w_2022_36/conda/envs/lsst-scipipe-4.1.0/lib/python3.10/site-packages/sqlalchemy/engine/base.py\", line 3394, in raw_connection\n    return self._wrap_pool_connect(self.pool.connect, _connection)\n\n  File \"/cvmfs/sw.lsst.eu/linux-x86_64/lsst_distrib/w_2022_36/conda/envs/lsst-scipipe-4.1.0/lib/python3.10/site-packages/sqlalchemy/engine/base.py\", line 3364, in _wrap_pool_connect\n    Connection._handle_dbapi_exception_noconnection(\n\n  File \"/cvmfs/sw.lsst.eu/linux-x86_64/lsst_distrib/w_2022_36/conda/envs/lsst-scipipe-4.1.0/lib/python3.10/site-packages/sqlalchemy/engine/base.py\", line 2198, in _handle_dbapi_exception_noconnection\n    util.raise_(\n\n  File \"/cvmfs/sw.lsst.eu/linux-x86_64/lsst_distrib/w_2022_36/conda/envs/lsst-scipipe-4.1.0/lib/python3.10/site-packages/sqlalchemy/util/compat.py\", line 208, in raise_\n    raise exception\n\n  File \"/cvmfs/sw.lsst.eu/linux-x86_64/lsst_distrib/w_2022_36/conda/envs/lsst-scipipe-4.1.0/lib/python3.10/site-packages/sqlalchemy/engine/base.py\", line 3361, in _wrap_pool_connect\n    return fn()\n\n  File \"/cvmfs/sw.lsst.eu/linux-x86_64/lsst_distrib/w_2022_36/conda/envs/lsst-scipipe-4.1.0/lib/python3.10/site-packages/sqlalchemy/pool/base.py\", line 310, in connect\n    return _ConnectionFairy._checkout(self)\n\n  File \"/cvmfs/sw.lsst.eu/linux-x86_64/lsst_distrib/w_2022_36/conda/envs/lsst-scipipe-4.1.0/lib/python3.10/site-packages/sqlalchemy/pool/base.py\", line 868, in _checkout\n    fairy = _ConnectionRecord.checkout(pool)\n\n  File \"/cvmfs/sw.lsst.eu/linux-x86_64/lsst_distrib/w_2022_36/conda/envs/lsst-scipipe-4.1.0/lib/python3.10/site-packages/sqlalchemy/pool/base.py\", line 476, in checkout\n    rec = pool._do_get()\n\n  File \"/cvmfs/sw.lsst.eu/linux-x86_64/lsst_distrib/w_2022_36/conda/envs/lsst-scipipe-4.1.0/lib/python3.10/site-packages/sqlalchemy/pool/impl.py\", line 145, in _do_get\n    with util.safe_reraise():\n\n  File \"/cvmfs/sw.lsst.eu/linux-x86_64/lsst_distrib/w_2022_36/conda/envs/lsst-scipipe-4.1.0/lib/python3.10/site-packages/sqlalchemy/util/langhelpers.py\", line 70, in __exit__\n    compat.raise_(\n\n  File \"/cvmfs/sw.lsst.eu/linux-x86_64/lsst_distrib/w_2022_36/conda/envs/lsst-scipipe-4.1.0/lib/python3.10/site-packages/sqlalchemy/util/compat.py\", line 208, in raise_\n    raise exception\n\n  File \"/cvmfs/sw.lsst.eu/linux-x86_64/lsst_distrib/w_2022_36/conda/envs/lsst-scipipe-4.1.0/lib/python3.10/site-packages/sqlalchemy/pool/impl.py\", line 143, in _do_get\n    return self._create_connection()\n\n  File \"/cvmfs/sw.lsst.eu/linux-x86_64/lsst_distrib/w_2022_36/conda/envs/lsst-scipipe-4.1.0/lib/python3.10/site-packages/sqlalchemy/pool/base.py\", line 256, in _create_connection\n    return _ConnectionRecord(self)\n\n  File \"/cvmfs/sw.lsst.eu/linux-x86_64/lsst_distrib/w_2022_36/conda/envs/lsst-scipipe-4.1.0/lib/python3.10/site-packages/sqlalchemy/pool/base.py\", line 371, in __init__\n    self.__connect()\n\n  File \"/cvmfs/sw.lsst.eu/linux-x86_64/lsst_distrib/w_2022_36/conda/envs/lsst-scipipe-4.1.0/lib/python3.10/site-packages/sqlalchemy/pool/base.py\", line 679, in __connect\n    )._exec_w_sync_on_first_run(self.dbapi_connection, self)\n\n  File \"/cvmfs/sw.lsst.eu/linux-x86_64/lsst_distrib/w_2022_36/conda/envs/lsst-scipipe-4.1.0/lib/python3.10/site-packages/sqlalchemy/event/attr.py\", line 329, in _exec_w_sync_on_first_run\n    self(*args, **kw)\n\n  File \"/cvmfs/sw.lsst.eu/linux-x86_64/lsst_distrib/w_2022_36/conda/envs/lsst-scipipe-4.1.0/lib/python3.10/site-packages/sqlalchemy/event/attr.py\", line 343, in __call__\n    fn(*args, **kw)\n\n  File \"/cvmfs/sw.lsst.eu/linux-x86_64/lsst_distrib/w_2022_36/conda/envs/lsst-scipipe-4.1.0/lib/python3.10/site-packages/sqlalchemy/engine/create.py\", line 658, in on_connect\n    do_on_connect(dbapi_connection)\n\n  File \"/cvmfs/sw.lsst.eu/linux-x86_64/lsst_distrib/w_2022_36/conda/envs/lsst-scipipe-4.1.0/lib/python3.10/site-packages/sqlalchemy/dialects/postgresql/psycopg2.py\", line 950, in on_connect\n    fn(conn)\n\n  File \"/cvmfs/sw.lsst.eu/linux-x86_64/lsst_distrib/w_2022_36/conda/envs/lsst-scipipe-4.1.0/lib/python3.10/site-packages/sqlalchemy/dialects/postgresql/psycopg2.py\", line 923, in on_connect\n    hstore_oids = self._hstore_oids(conn)\n\n  File \"/cvmfs/sw.lsst.eu/linux-x86_64/lsst_distrib/w_2022_36/conda/envs/lsst-scipipe-4.1.0/lib/python3.10/site-packages/sqlalchemy/util/langhelpers.py\", line 1134, in oneshot\n    result = fn(self, *args, **kw)\n\n  File \"/cvmfs/sw.lsst.eu/linux-x86_64/lsst_distrib/w_2022_36/conda/envs/lsst-scipipe-4.1.0/lib/python3.10/site-packages/sqlalchemy/dialects/postgresql/psycopg2.py\", line 1007, in _hstore_oids\n    oids = extras.HstoreAdapter.get_oids(conn)\n\n  File \"/cvmfs/sw.lsst.eu/linux-x86_64/lsst_distrib/w_2022_36/conda/envs/lsst-scipipe-4.1.0/lib/python3.10/site-packages/psycopg2/extras.py\", line 911, in get_oids\n    curs.execute(f\"\"\"SELECT t.oid, {typarray}\n\nsqlalchemy.exc.OperationalError: (psycopg2.OperationalError) query_wait_timeout\nSSL connection has been closed unexpectedly\n\n(Background on this error at: https://sqlalche.me/e/14/e3q8)\n", "MDC": {}}
{"name": "lsst.daf.butler._butler", "asctime": "2022-09-06T23:11:12.149803+00:00", "message": "Failed to instantiate Butler from config file:///sdf/group/rubin/repo/main_20220411/butler.yaml.", "levelno": 40, "levelname": "ERROR", "filename": "_butler.py", "pathname": "/cvmfs/sw.lsst.eu/linux-x86_64/lsst_distrib/w_2022_36/conda/envs/lsst-scipipe-4.1.0/share/eups/Linux64/daf_butler/g3ee7dd65e6+24e5aa5155/python/lsst/daf/butler/_butler.py", "lineno": 295, "funcName": "__init__", "process": 11489, "processName": "MainProcess", "MDC": {}}
{"name": "lsst.daf.butler.cli.utils", "asctime": "2022-09-06T23:11:12.168225+00:00", "message": "Caught an exception, details are in traceback:", "levelno": 40, "levelname": "ERROR", "filename": "utils.py", "pathname": "/cvmfs/sw.lsst.eu/linux-x86_64/lsst_distrib/w_2022_36/conda/envs/lsst-scipipe-4.1.0/share/eups/Linux64/daf_butler/g3ee7dd65e6+24e5aa5155/python/lsst/daf/butler/cli/utils.py", "lineno": 1093, "funcName": "inner", "process": 11489, "processName": "MainProcess", "exc_info": "Traceback (most recent call last):\n\n  File \"/cvmfs/sw.lsst.eu/linux-x86_64/lsst_distrib/w_2022_36/conda/envs/lsst-scipipe-4.1.0/lib/python3.10/site-packages/sqlalchemy/engine/base.py\", line 3361, in _wrap_pool_connect\n    return fn()\n\n  File \"/cvmfs/sw.lsst.eu/linux-x86_64/lsst_distrib/w_2022_36/conda/envs/lsst-scipipe-4.1.0/lib/python3.10/site-packages/sqlalchemy/pool/base.py\", line 310, in connect\n    return _ConnectionFairy._checkout(self)\n\n  File \"/cvmfs/sw.lsst.eu/linux-x86_64/lsst_distrib/w_2022_36/conda/envs/lsst-scipipe-4.1.0/lib/python3.10/site-packages/sqlalchemy/pool/base.py\", line 868, in _checkout\n    fairy = _ConnectionRecord.checkout(pool)\n\n  File \"/cvmfs/sw.lsst.eu/linux-x86_64/lsst_distrib/w_2022_36/conda/envs/lsst-scipipe-4.1.0/lib/python3.10/site-packages/sqlalchemy/pool/base.py\", line 476, in checkout\n    rec = pool._do_get()\n\n  File \"/cvmfs/sw.lsst.eu/linux-x86_64/lsst_distrib/w_2022_36/conda/envs/lsst-scipipe-4.1.0/lib/python3.10/site-packages/sqlalchemy/pool/impl.py\", line 145, in _do_get\n    with util.safe_reraise():\n\n  File \"/cvmfs/sw.lsst.eu/linux-x86_64/lsst_distrib/w_2022_36/conda/envs/lsst-scipipe-4.1.0/lib/python3.10/site-packages/sqlalchemy/util/langhelpers.py\", line 70, in __exit__\n    compat.raise_(\n\n  File \"/cvmfs/sw.lsst.eu/linux-x86_64/lsst_distrib/w_2022_36/conda/envs/lsst-scipipe-4.1.0/lib/python3.10/site-packages/sqlalchemy/util/compat.py\", line 208, in raise_\n    raise exception\n\n  File \"/cvmfs/sw.lsst.eu/linux-x86_64/lsst_distrib/w_2022_36/conda/envs/lsst-scipipe-4.1.0/lib/python3.10/site-packages/sqlalchemy/pool/impl.py\", line 143, in _do_get\n    return self._create_connection()\n\n  File \"/cvmfs/sw.lsst.eu/linux-x86_64/lsst_distrib/w_2022_36/conda/envs/lsst-scipipe-4.1.0/lib/python3.10/site-packages/sqlalchemy/pool/base.py\", line 256, in _create_connection\n    return _ConnectionRecord(self)\n\n  File \"/cvmfs/sw.lsst.eu/linux-x86_64/lsst_distrib/w_2022_36/conda/envs/lsst-scipipe-4.1.0/lib/python3.10/site-packages/sqlalchemy/pool/base.py\", line 371, in __init__\n    self.__connect()\n\n  File \"/cvmfs/sw.lsst.eu/linux-x86_64/lsst_distrib/w_2022_36/conda/envs/lsst-scipipe-4.1.0/lib/python3.10/site-packages/sqlalchemy/pool/base.py\", line 679, in __connect\n    )._exec_w_sync_on_first_run(self.dbapi_connection, self)\n\n  File \"/cvmfs/sw.lsst.eu/linux-x86_64/lsst_distrib/w_2022_36/conda/envs/lsst-scipipe-4.1.0/lib/python3.10/site-packages/sqlalchemy/event/attr.py\", line 329, in _exec_w_sync_on_first_run\n    self(*args, **kw)\n\n  File \"/cvmfs/sw.lsst.eu/linux-x86_64/lsst_distrib/w_2022_36/conda/envs/lsst-scipipe-4.1.0/lib/python3.10/site-packages/sqlalchemy/event/attr.py\", line 343, in __call__\n    fn(*args, **kw)\n\n  File \"/cvmfs/sw.lsst.eu/linux-x86_64/lsst_distrib/w_2022_36/conda/envs/lsst-scipipe-4.1.0/lib/python3.10/site-packages/sqlalchemy/engine/create.py\", line 658, in on_connect\n    do_on_connect(dbapi_connection)\n\n  File \"/cvmfs/sw.lsst.eu/linux-x86_64/lsst_distrib/w_2022_36/conda/envs/lsst-scipipe-4.1.0/lib/python3.10/site-packages/sqlalchemy/dialects/postgresql/psycopg2.py\", line 950, in on_connect\n    fn(conn)\n\n  File \"/cvmfs/sw.lsst.eu/linux-x86_64/lsst_distrib/w_2022_36/conda/envs/lsst-scipipe-4.1.0/lib/python3.10/site-packages/sqlalchemy/dialects/postgresql/psycopg2.py\", line 923, in on_connect\n    hstore_oids = self._hstore_oids(conn)\n\n  File \"/cvmfs/sw.lsst.eu/linux-x86_64/lsst_distrib/w_2022_36/conda/envs/lsst-scipipe-4.1.0/lib/python3.10/site-packages/sqlalchemy/util/langhelpers.py\", line 1134, in oneshot\n    result = fn(self, *args, **kw)\n\n  File \"/cvmfs/sw.lsst.eu/linux-x86_64/lsst_distrib/w_2022_36/conda/envs/lsst-scipipe-4.1.0/lib/python3.10/site-packages/sqlalchemy/dialects/postgresql/psycopg2.py\", line 1007, in _hstore_oids\n    oids = extras.HstoreAdapter.get_oids(conn)\n\n  File \"/cvmfs/sw.lsst.eu/linux-x86_64/lsst_distrib/w_2022_36/conda/envs/lsst-scipipe-4.1.0/lib/python3.10/site-packages/psycopg2/extras.py\", line 911, in get_oids\n    curs.execute(f\"\"\"SELECT t.oid, {typarray}\n\npsycopg2.OperationalError: query_wait_timeout\nSSL connection has been closed unexpectedly\n\n\n\nThe above exception was the direct cause of the following exception:\n\n\nTraceback (most recent call last):\n\n  File \"/cvmfs/sw.lsst.eu/linux-x86_64/lsst_distrib/w_2022_36/conda/envs/lsst-scipipe-4.1.0/share/eups/Linux64/ctrl_mpexec/g5106228df7+1629eaad64/python/lsst/ctrl/mpexec/cli/cmd/commands.py\", line 140, in qgraph\n    script.qgraph(pipelineObj=pipeline, **kwargs, show=show)\n\n  File \"/cvmfs/sw.lsst.eu/linux-x86_64/lsst_distrib/w_2022_36/conda/envs/lsst-scipipe-4.1.0/share/eups/Linux64/ctrl_mpexec/g5106228df7+1629eaad64/python/lsst/ctrl/mpexec/cli/script/qgraph.py\", line 196, in qgraph\n    qgraph = f.makeGraph(pipelineObj, args)\n\n  File \"/cvmfs/sw.lsst.eu/linux-x86_64/lsst_distrib/w_2022_36/conda/envs/lsst-scipipe-4.1.0/share/eups/Linux64/ctrl_mpexec/g5106228df7+1629eaad64/python/lsst/ctrl/mpexec/cmdLineFwk.py\", line 525, in makeGraph\n    butler, collections, run = _ButlerFactory.makeButlerAndCollections(args)\n\n  File \"/cvmfs/sw.lsst.eu/linux-x86_64/lsst_distrib/w_2022_36/conda/envs/lsst-scipipe-4.1.0/share/eups/Linux64/ctrl_mpexec/g5106228df7+1629eaad64/python/lsst/ctrl/mpexec/cmdLineFwk.py\", line 347, in makeButlerAndCollections\n    butler, inputs, self = cls._makeReadParts(args)\n\n  File \"/cvmfs/sw.lsst.eu/linux-x86_64/lsst_distrib/w_2022_36/conda/envs/lsst-scipipe-4.1.0/share/eups/Linux64/ctrl_mpexec/g5106228df7+1629eaad64/python/lsst/ctrl/mpexec/cmdLineFwk.py\", line 282, in _makeReadParts\n    butler = Butler(args.butler_config, writeable=False)\n\n  File \"/cvmfs/sw.lsst.eu/linux-x86_64/lsst_distrib/w_2022_36/conda/envs/lsst-scipipe-4.1.0/share/eups/Linux64/daf_butler/g3ee7dd65e6+24e5aa5155/python/lsst/daf/butler/_butler.py\", line 281, in __init__\n    self.registry = Registry.fromConfig(\n\n  File \"/cvmfs/sw.lsst.eu/linux-x86_64/lsst_distrib/w_2022_36/conda/envs/lsst-scipipe-4.1.0/share/eups/Linux64/daf_butler/g3ee7dd65e6+24e5aa5155/python/lsst/daf/butler/registry/_registry.py\", line 230, in fromConfig\n    return registry_cls.fromConfig(config, butlerRoot, writeable, defaults)\n\n  File \"/cvmfs/sw.lsst.eu/linux-x86_64/lsst_distrib/w_2022_36/conda/envs/lsst-scipipe-4.1.0/share/eups/Linux64/daf_butler/g3ee7dd65e6+24e5aa5155/python/lsst/daf/butler/registries/sql.py\", line 188, in fromConfig\n    database = DatabaseClass.fromUri(\n\n  File \"/cvmfs/sw.lsst.eu/linux-x86_64/lsst_distrib/w_2022_36/conda/envs/lsst-scipipe-4.1.0/share/eups/Linux64/daf_butler/g3ee7dd65e6+24e5aa5155/python/lsst/daf/butler/registry/interfaces/_database.py\", line 366, in fromUri\n    return cls.fromEngine(\n\n  File \"/cvmfs/sw.lsst.eu/linux-x86_64/lsst_distrib/w_2022_36/conda/envs/lsst-scipipe-4.1.0/share/eups/Linux64/daf_butler/g3ee7dd65e6+24e5aa5155/python/lsst/daf/butler/registry/databases/postgresql.py\", line 110, in fromEngine\n    return cls(engine=engine, origin=origin, namespace=namespace, writeable=writeable)\n\n  File \"/cvmfs/sw.lsst.eu/linux-x86_64/lsst_distrib/w_2022_36/conda/envs/lsst-scipipe-4.1.0/share/eups/Linux64/daf_butler/g3ee7dd65e6+24e5aa5155/python/lsst/daf/butler/registry/databases/postgresql.py\", line 76, in __init__\n    with engine.connect() as connection:\n\n  File \"/cvmfs/sw.lsst.eu/linux-x86_64/lsst_distrib/w_2022_36/conda/envs/lsst-scipipe-4.1.0/lib/python3.10/site-packages/sqlalchemy/engine/base.py\", line 3315, in connect\n    return self._connection_cls(self, close_with_result=close_with_result)\n\n  File \"/cvmfs/sw.lsst.eu/linux-x86_64/lsst_distrib/w_2022_36/conda/envs/lsst-scipipe-4.1.0/lib/python3.10/site-packages/sqlalchemy/engine/base.py\", line 96, in __init__\n    else engine.raw_connection()\n\n  File \"/cvmfs/sw.lsst.eu/linux-x86_64/lsst_distrib/w_2022_36/conda/envs/lsst-scipipe-4.1.0/lib/python3.10/site-packages/sqlalchemy/engine/base.py\", line 3394, in raw_connection\n    return self._wrap_pool_connect(self.pool.connect, _connection)\n\n  File \"/cvmfs/sw.lsst.eu/linux-x86_64/lsst_distrib/w_2022_36/conda/envs/lsst-scipipe-4.1.0/lib/python3.10/site-packages/sqlalchemy/engine/base.py\", line 3364, in _wrap_pool_connect\n    Connection._handle_dbapi_exception_noconnection(\n\n  File \"/cvmfs/sw.lsst.eu/linux-x86_64/lsst_distrib/w_2022_36/conda/envs/lsst-scipipe-4.1.0/lib/python3.10/site-packages/sqlalchemy/engine/base.py\", line 2198, in _handle_dbapi_exception_noconnection\n    util.raise_(\n\n  File \"/cvmfs/sw.lsst.eu/linux-x86_64/lsst_distrib/w_2022_36/conda/envs/lsst-scipipe-4.1.0/lib/python3.10/site-packages/sqlalchemy/util/compat.py\", line 208, in raise_\n    raise exception\n\n  File \"/cvmfs/sw.lsst.eu/linux-x86_64/lsst_distrib/w_2022_36/conda/envs/lsst-scipipe-4.1.0/lib/python3.10/site-packages/sqlalchemy/engine/base.py\", line 3361, in _wrap_pool_connect\n    return fn()\n\n  File \"/cvmfs/sw.lsst.eu/linux-x86_64/lsst_distrib/w_2022_36/conda/envs/lsst-scipipe-4.1.0/lib/python3.10/site-packages/sqlalchemy/pool/base.py\", line 310, in connect\n    return _ConnectionFairy._checkout(self)\n\n  File \"/cvmfs/sw.lsst.eu/linux-x86_64/lsst_distrib/w_2022_36/conda/envs/lsst-scipipe-4.1.0/lib/python3.10/site-packages/sqlalchemy/pool/base.py\", line 868, in _checkout\n    fairy = _ConnectionRecord.checkout(pool)\n\n  File \"/cvmfs/sw.lsst.eu/linux-x86_64/lsst_distrib/w_2022_36/conda/envs/lsst-scipipe-4.1.0/lib/python3.10/site-packages/sqlalchemy/pool/base.py\", line 476, in checkout\n    rec = pool._do_get()\n\n  File \"/cvmfs/sw.lsst.eu/linux-x86_64/lsst_distrib/w_2022_36/conda/envs/lsst-scipipe-4.1.0/lib/python3.10/site-packages/sqlalchemy/pool/impl.py\", line 145, in _do_get\n    with util.safe_reraise():\n\n  File \"/cvmfs/sw.lsst.eu/linux-x86_64/lsst_distrib/w_2022_36/conda/envs/lsst-scipipe-4.1.0/lib/python3.10/site-packages/sqlalchemy/util/langhelpers.py\", line 70, in __exit__\n    compat.raise_(\n\n  File \"/cvmfs/sw.lsst.eu/linux-x86_64/lsst_distrib/w_2022_36/conda/envs/lsst-scipipe-4.1.0/lib/python3.10/site-packages/sqlalchemy/util/compat.py\", line 208, in raise_\n    raise exception\n\n  File \"/cvmfs/sw.lsst.eu/linux-x86_64/lsst_distrib/w_2022_36/conda/envs/lsst-scipipe-4.1.0/lib/python3.10/site-packages/sqlalchemy/pool/impl.py\", line 143, in _do_get\n    return self._create_connection()\n\n  File \"/cvmfs/sw.lsst.eu/linux-x86_64/lsst_distrib/w_2022_36/conda/envs/lsst-scipipe-4.1.0/lib/python3.10/site-packages/sqlalchemy/pool/base.py\", line 256, in _create_connection\n    return _ConnectionRecord(self)\n\n  File \"/cvmfs/sw.lsst.eu/linux-x86_64/lsst_distrib/w_2022_36/conda/envs/lsst-scipipe-4.1.0/lib/python3.10/site-packages/sqlalchemy/pool/base.py\", line 371, in __init__\n    self.__connect()\n\n  File \"/cvmfs/sw.lsst.eu/linux-x86_64/lsst_distrib/w_2022_36/conda/envs/lsst-scipipe-4.1.0/lib/python3.10/site-packages/sqlalchemy/pool/base.py\", line 679, in __connect\n    )._exec_w_sync_on_first_run(self.dbapi_connection, self)\n\n  File \"/cvmfs/sw.lsst.eu/linux-x86_64/lsst_distrib/w_2022_36/conda/envs/lsst-scipipe-4.1.0/lib/python3.10/site-packages/sqlalchemy/event/attr.py\", line 329, in _exec_w_sync_on_first_run\n    self(*args, **kw)\n\n  File \"/cvmfs/sw.lsst.eu/linux-x86_64/lsst_distrib/w_2022_36/conda/envs/lsst-scipipe-4.1.0/lib/python3.10/site-packages/sqlalchemy/event/attr.py\", line 343, in __call__\n    fn(*args, **kw)\n\n  File \"/cvmfs/sw.lsst.eu/linux-x86_64/lsst_distrib/w_2022_36/conda/envs/lsst-scipipe-4.1.0/lib/python3.10/site-packages/sqlalchemy/engine/create.py\", line 658, in on_connect\n    do_on_connect(dbapi_connection)\n\n  File \"/cvmfs/sw.lsst.eu/linux-x86_64/lsst_distrib/w_2022_36/conda/envs/lsst-scipipe-4.1.0/lib/python3.10/site-packages/sqlalchemy/dialects/postgresql/psycopg2.py\", line 950, in on_connect\n    fn(conn)\n\n  File \"/cvmfs/sw.lsst.eu/linux-x86_64/lsst_distrib/w_2022_36/conda/envs/lsst-scipipe-4.1.0/lib/python3.10/site-packages/sqlalchemy/dialects/postgresql/psycopg2.py\", line 923, in on_connect\n    hstore_oids = self._hstore_oids(conn)\n\n  File \"/cvmfs/sw.lsst.eu/linux-x86_64/lsst_distrib/w_2022_36/conda/envs/lsst-scipipe-4.1.0/lib/python3.10/site-packages/sqlalchemy/util/langhelpers.py\", line 1134, in oneshot\n    result = fn(self, *args, **kw)\n\n  File \"/cvmfs/sw.lsst.eu/linux-x86_64/lsst_distrib/w_2022_36/conda/envs/lsst-scipipe-4.1.0/lib/python3.10/site-packages/sqlalchemy/dialects/postgresql/psycopg2.py\", line 1007, in _hstore_oids\n    oids = extras.HstoreAdapter.get_oids(conn)\n\n  File \"/cvmfs/sw.lsst.eu/linux-x86_64/lsst_distrib/w_2022_36/conda/envs/lsst-scipipe-4.1.0/lib/python3.10/site-packages/psycopg2/extras.py\", line 911, in get_oids\n    curs.execute(f\"\"\"SELECT t.oid, {typarray}\n\nsqlalchemy.exc.OperationalError: (psycopg2.OperationalError) query_wait_timeout\nSSL connection has been closed unexpectedly\n\n(Background on this error at: https://sqlalche.me/e/14/e3q8)\n", "MDC": {}}
{"name": "lsst.daf.butler._butler", "asctime": "2022-09-06T23:14:19.623064+00:00", "message": "Failed to instantiate Butler from config file:///sdf/group/rubin/repo/main_20220411/butler.yaml.", "levelno": 40, "levelname": "ERROR", "filename": "_butler.py", "pathname": "/cvmfs/sw.lsst.eu/linux-x86_64/lsst_distrib/w_2022_36/conda/envs/lsst-scipipe-4.1.0/share/eups/Linux64/daf_butler/g3ee7dd65e6+24e5aa5155/python/lsst/daf/butler/_butler.py", "lineno": 295, "funcName": "__init__", "process": 12004, "processName": "MainProcess", "MDC": {}}
{"name": "lsst.daf.butler.cli.utils", "asctime": "2022-09-06T23:14:19.624966+00:00", "message": "Caught an exception, details are in traceback:", "levelno": 40, "levelname": "ERROR", "filename": "utils.py", "pathname": "/cvmfs/sw.lsst.eu/linux-x86_64/lsst_distrib/w_2022_36/conda/envs/lsst-scipipe-4.1.0/share/eups/Linux64/daf_butler/g3ee7dd65e6+24e5aa5155/python/lsst/daf/butler/cli/utils.py", "lineno": 1093, "funcName": "inner", "process": 12004, "processName": "MainProcess", "exc_info": "Traceback (most recent call last):\n\n  File \"/cvmfs/sw.lsst.eu/linux-x86_64/lsst_distrib/w_2022_36/conda/envs/lsst-scipipe-4.1.0/lib/python3.10/site-packages/sqlalchemy/engine/base.py\", line 3361, in _wrap_pool_connect\n    return fn()\n\n  File \"/cvmfs/sw.lsst.eu/linux-x86_64/lsst_distrib/w_2022_36/conda/envs/lsst-scipipe-4.1.0/lib/python3.10/site-packages/sqlalchemy/pool/base.py\", line 310, in connect\n    return _ConnectionFairy._checkout(self)\n\n  File \"/cvmfs/sw.lsst.eu/linux-x86_64/lsst_distrib/w_2022_36/conda/envs/lsst-scipipe-4.1.0/lib/python3.10/site-packages/sqlalchemy/pool/base.py\", line 868, in _checkout\n    fairy = _ConnectionRecord.checkout(pool)\n\n  File \"/cvmfs/sw.lsst.eu/linux-x86_64/lsst_distrib/w_2022_36/conda/envs/lsst-scipipe-4.1.0/lib/python3.10/site-packages/sqlalchemy/pool/base.py\", line 476, in checkout\n    rec = pool._do_get()\n\n  File \"/cvmfs/sw.lsst.eu/linux-x86_64/lsst_distrib/w_2022_36/conda/envs/lsst-scipipe-4.1.0/lib/python3.10/site-packages/sqlalchemy/pool/impl.py\", line 145, in _do_get\n    with util.safe_reraise():\n\n  File \"/cvmfs/sw.lsst.eu/linux-x86_64/lsst_distrib/w_2022_36/conda/envs/lsst-scipipe-4.1.0/lib/python3.10/site-packages/sqlalchemy/util/langhelpers.py\", line 70, in __exit__\n    compat.raise_(\n\n  File \"/cvmfs/sw.lsst.eu/linux-x86_64/lsst_distrib/w_2022_36/conda/envs/lsst-scipipe-4.1.0/lib/python3.10/site-packages/sqlalchemy/util/compat.py\", line 208, in raise_\n    raise exception\n\n  File \"/cvmfs/sw.lsst.eu/linux-x86_64/lsst_distrib/w_2022_36/conda/envs/lsst-scipipe-4.1.0/lib/python3.10/site-packages/sqlalchemy/pool/impl.py\", line 143, in _do_get\n    return self._create_connection()\n\n  File \"/cvmfs/sw.lsst.eu/linux-x86_64/lsst_distrib/w_2022_36/conda/envs/lsst-scipipe-4.1.0/lib/python3.10/site-packages/sqlalchemy/pool/base.py\", line 256, in _create_connection\n    return _ConnectionRecord(self)\n\n  File \"/cvmfs/sw.lsst.eu/linux-x86_64/lsst_distrib/w_2022_36/conda/envs/lsst-scipipe-4.1.0/lib/python3.10/site-packages/sqlalchemy/pool/base.py\", line 371, in __init__\n    self.__connect()\n\n  File \"/cvmfs/sw.lsst.eu/linux-x86_64/lsst_distrib/w_2022_36/conda/envs/lsst-scipipe-4.1.0/lib/python3.10/site-packages/sqlalchemy/pool/base.py\", line 679, in __connect\n    )._exec_w_sync_on_first_run(self.dbapi_connection, self)\n\n  File \"/cvmfs/sw.lsst.eu/linux-x86_64/lsst_distrib/w_2022_36/conda/envs/lsst-scipipe-4.1.0/lib/python3.10/site-packages/sqlalchemy/event/attr.py\", line 329, in _exec_w_sync_on_first_run\n    self(*args, **kw)\n\n  File \"/cvmfs/sw.lsst.eu/linux-x86_64/lsst_distrib/w_2022_36/conda/envs/lsst-scipipe-4.1.0/lib/python3.10/site-packages/sqlalchemy/event/attr.py\", line 343, in __call__\n    fn(*args, **kw)\n\n  File \"/cvmfs/sw.lsst.eu/linux-x86_64/lsst_distrib/w_2022_36/conda/envs/lsst-scipipe-4.1.0/lib/python3.10/site-packages/sqlalchemy/engine/create.py\", line 658, in on_connect\n    do_on_connect(dbapi_connection)\n\n  File \"/cvmfs/sw.lsst.eu/linux-x86_64/lsst_distrib/w_2022_36/conda/envs/lsst-scipipe-4.1.0/lib/python3.10/site-packages/sqlalchemy/dialects/postgresql/psycopg2.py\", line 950, in on_connect\n    fn(conn)\n\n  File \"/cvmfs/sw.lsst.eu/linux-x86_64/lsst_distrib/w_2022_36/conda/envs/lsst-scipipe-4.1.0/lib/python3.10/site-packages/sqlalchemy/dialects/postgresql/psycopg2.py\", line 923, in on_connect\n    hstore_oids = self._hstore_oids(conn)\n\n  File \"/cvmfs/sw.lsst.eu/linux-x86_64/lsst_distrib/w_2022_36/conda/envs/lsst-scipipe-4.1.0/lib/python3.10/site-packages/sqlalchemy/util/langhelpers.py\", line 1134, in oneshot\n    result = fn(self, *args, **kw)\n\n  File \"/cvmfs/sw.lsst.eu/linux-x86_64/lsst_distrib/w_2022_36/conda/envs/lsst-scipipe-4.1.0/lib/python3.10/site-packages/sqlalchemy/dialects/postgresql/psycopg2.py\", line 1007, in _hstore_oids\n    oids = extras.HstoreAdapter.get_oids(conn)\n\n  File \"/cvmfs/sw.lsst.eu/linux-x86_64/lsst_distrib/w_2022_36/conda/envs/lsst-scipipe-4.1.0/lib/python3.10/site-packages/psycopg2/extras.py\", line 911, in get_oids\n    curs.execute(f\"\"\"SELECT t.oid, {typarray}\n\npsycopg2.OperationalError: query_wait_timeout\nSSL connection has been closed unexpectedly\n\n\n\nThe above exception was the direct cause of the following exception:\n\n\nTraceback (most recent call last):\n\n  File \"/cvmfs/sw.lsst.eu/linux-x86_64/lsst_distrib/w_2022_36/conda/envs/lsst-scipipe-4.1.0/share/eups/Linux64/ctrl_mpexec/g5106228df7+1629eaad64/python/lsst/ctrl/mpexec/cli/cmd/commands.py\", line 140, in qgraph\n    script.qgraph(pipelineObj=pipeline, **kwargs, show=show)\n\n  File \"/cvmfs/sw.lsst.eu/linux-x86_64/lsst_distrib/w_2022_36/conda/envs/lsst-scipipe-4.1.0/share/eups/Linux64/ctrl_mpexec/g5106228df7+1629eaad64/python/lsst/ctrl/mpexec/cli/script/qgraph.py\", line 196, in qgraph\n    qgraph = f.makeGraph(pipelineObj, args)\n\n  File \"/cvmfs/sw.lsst.eu/linux-x86_64/lsst_distrib/w_2022_36/conda/envs/lsst-scipipe-4.1.0/share/eups/Linux64/ctrl_mpexec/g5106228df7+1629eaad64/python/lsst/ctrl/mpexec/cmdLineFwk.py\", line 525, in makeGraph\n    butler, collections, run = _ButlerFactory.makeButlerAndCollections(args)\n\n  File \"/cvmfs/sw.lsst.eu/linux-x86_64/lsst_distrib/w_2022_36/conda/envs/lsst-scipipe-4.1.0/share/eups/Linux64/ctrl_mpexec/g5106228df7+1629eaad64/python/lsst/ctrl/mpexec/cmdLineFwk.py\", line 347, in makeButlerAndCollections\n    butler, inputs, self = cls._makeReadParts(args)\n\n  File \"/cvmfs/sw.lsst.eu/linux-x86_64/lsst_distrib/w_2022_36/conda/envs/lsst-scipipe-4.1.0/share/eups/Linux64/ctrl_mpexec/g5106228df7+1629eaad64/python/lsst/ctrl/mpexec/cmdLineFwk.py\", line 282, in _makeReadParts\n    butler = Butler(args.butler_config, writeable=False)\n\n  File \"/cvmfs/sw.lsst.eu/linux-x86_64/lsst_distrib/w_2022_36/conda/envs/lsst-scipipe-4.1.0/share/eups/Linux64/daf_butler/g3ee7dd65e6+24e5aa5155/python/lsst/daf/butler/_butler.py\", line 281, in __init__\n    self.registry = Registry.fromConfig(\n\n  File \"/cvmfs/sw.lsst.eu/linux-x86_64/lsst_distrib/w_2022_36/conda/envs/lsst-scipipe-4.1.0/share/eups/Linux64/daf_butler/g3ee7dd65e6+24e5aa5155/python/lsst/daf/butler/registry/_registry.py\", line 230, in fromConfig\n    return registry_cls.fromConfig(config, butlerRoot, writeable, defaults)\n\n  File \"/cvmfs/sw.lsst.eu/linux-x86_64/lsst_distrib/w_2022_36/conda/envs/lsst-scipipe-4.1.0/share/eups/Linux64/daf_butler/g3ee7dd65e6+24e5aa5155/python/lsst/daf/butler/registries/sql.py\", line 188, in fromConfig\n    database = DatabaseClass.fromUri(\n\n  File \"/cvmfs/sw.lsst.eu/linux-x86_64/lsst_distrib/w_2022_36/conda/envs/lsst-scipipe-4.1.0/share/eups/Linux64/daf_butler/g3ee7dd65e6+24e5aa5155/python/lsst/daf/butler/registry/interfaces/_database.py\", line 366, in fromUri\n    return cls.fromEngine(\n\n  File \"/cvmfs/sw.lsst.eu/linux-x86_64/lsst_distrib/w_2022_36/conda/envs/lsst-scipipe-4.1.0/share/eups/Linux64/daf_butler/g3ee7dd65e6+24e5aa5155/python/lsst/daf/butler/registry/databases/postgresql.py\", line 110, in fromEngine\n    return cls(engine=engine, origin=origin, namespace=namespace, writeable=writeable)\n\n  File \"/cvmfs/sw.lsst.eu/linux-x86_64/lsst_distrib/w_2022_36/conda/envs/lsst-scipipe-4.1.0/share/eups/Linux64/daf_butler/g3ee7dd65e6+24e5aa5155/python/lsst/daf/butler/registry/databases/postgresql.py\", line 76, in __init__\n    with engine.connect() as connection:\n\n  File \"/cvmfs/sw.lsst.eu/linux-x86_64/lsst_distrib/w_2022_36/conda/envs/lsst-scipipe-4.1.0/lib/python3.10/site-packages/sqlalchemy/engine/base.py\", line 3315, in connect\n    return self._connection_cls(self, close_with_result=close_with_result)\n\n  File \"/cvmfs/sw.lsst.eu/linux-x86_64/lsst_distrib/w_2022_36/conda/envs/lsst-scipipe-4.1.0/lib/python3.10/site-packages/sqlalchemy/engine/base.py\", line 96, in __init__\n    else engine.raw_connection()\n\n  File \"/cvmfs/sw.lsst.eu/linux-x86_64/lsst_distrib/w_2022_36/conda/envs/lsst-scipipe-4.1.0/lib/python3.10/site-packages/sqlalchemy/engine/base.py\", line 3394, in raw_connection\n    return self._wrap_pool_connect(self.pool.connect, _connection)\n\n  File \"/cvmfs/sw.lsst.eu/linux-x86_64/lsst_distrib/w_2022_36/conda/envs/lsst-scipipe-4.1.0/lib/python3.10/site-packages/sqlalchemy/engine/base.py\", line 3364, in _wrap_pool_connect\n    Connection._handle_dbapi_exception_noconnection(\n\n  File \"/cvmfs/sw.lsst.eu/linux-x86_64/lsst_distrib/w_2022_36/conda/envs/lsst-scipipe-4.1.0/lib/python3.10/site-packages/sqlalchemy/engine/base.py\", line 2198, in _handle_dbapi_exception_noconnection\n    util.raise_(\n\n  File \"/cvmfs/sw.lsst.eu/linux-x86_64/lsst_distrib/w_2022_36/conda/envs/lsst-scipipe-4.1.0/lib/python3.10/site-packages/sqlalchemy/util/compat.py\", line 208, in raise_\n    raise exception\n\n  File \"/cvmfs/sw.lsst.eu/linux-x86_64/lsst_distrib/w_2022_36/conda/envs/lsst-scipipe-4.1.0/lib/python3.10/site-packages/sqlalchemy/engine/base.py\", line 3361, in _wrap_pool_connect\n    return fn()\n\n  File \"/cvmfs/sw.lsst.eu/linux-x86_64/lsst_distrib/w_2022_36/conda/envs/lsst-scipipe-4.1.0/lib/python3.10/site-packages/sqlalchemy/pool/base.py\", line 310, in connect\n    return _ConnectionFairy._checkout(self)\n\n  File \"/cvmfs/sw.lsst.eu/linux-x86_64/lsst_distrib/w_2022_36/conda/envs/lsst-scipipe-4.1.0/lib/python3.10/site-packages/sqlalchemy/pool/base.py\", line 868, in _checkout\n    fairy = _ConnectionRecord.checkout(pool)\n\n  File \"/cvmfs/sw.lsst.eu/linux-x86_64/lsst_distrib/w_2022_36/conda/envs/lsst-scipipe-4.1.0/lib/python3.10/site-packages/sqlalchemy/pool/base.py\", line 476, in checkout\n    rec = pool._do_get()\n\n  File \"/cvmfs/sw.lsst.eu/linux-x86_64/lsst_distrib/w_2022_36/conda/envs/lsst-scipipe-4.1.0/lib/python3.10/site-packages/sqlalchemy/pool/impl.py\", line 145, in _do_get\n    with util.safe_reraise():\n\n  File \"/cvmfs/sw.lsst.eu/linux-x86_64/lsst_distrib/w_2022_36/conda/envs/lsst-scipipe-4.1.0/lib/python3.10/site-packages/sqlalchemy/util/langhelpers.py\", line 70, in __exit__\n    compat.raise_(\n\n  File \"/cvmfs/sw.lsst.eu/linux-x86_64/lsst_distrib/w_2022_36/conda/envs/lsst-scipipe-4.1.0/lib/python3.10/site-packages/sqlalchemy/util/compat.py\", line 208, in raise_\n    raise exception\n\n  File \"/cvmfs/sw.lsst.eu/linux-x86_64/lsst_distrib/w_2022_36/conda/envs/lsst-scipipe-4.1.0/lib/python3.10/site-packages/sqlalchemy/pool/impl.py\", line 143, in _do_get\n    return self._create_connection()\n\n  File \"/cvmfs/sw.lsst.eu/linux-x86_64/lsst_distrib/w_2022_36/conda/envs/lsst-scipipe-4.1.0/lib/python3.10/site-packages/sqlalchemy/pool/base.py\", line 256, in _create_connection\n    return _ConnectionRecord(self)\n\n  File \"/cvmfs/sw.lsst.eu/linux-x86_64/lsst_distrib/w_2022_36/conda/envs/lsst-scipipe-4.1.0/lib/python3.10/site-packages/sqlalchemy/pool/base.py\", line 371, in __init__\n    self.__connect()\n\n  File \"/cvmfs/sw.lsst.eu/linux-x86_64/lsst_distrib/w_2022_36/conda/envs/lsst-scipipe-4.1.0/lib/python3.10/site-packages/sqlalchemy/pool/base.py\", line 679, in __connect\n    )._exec_w_sync_on_first_run(self.dbapi_connection, self)\n\n  File \"/cvmfs/sw.lsst.eu/linux-x86_64/lsst_distrib/w_2022_36/conda/envs/lsst-scipipe-4.1.0/lib/python3.10/site-packages/sqlalchemy/event/attr.py\", line 329, in _exec_w_sync_on_first_run\n    self(*args, **kw)\n\n  File \"/cvmfs/sw.lsst.eu/linux-x86_64/lsst_distrib/w_2022_36/conda/envs/lsst-scipipe-4.1.0/lib/python3.10/site-packages/sqlalchemy/event/attr.py\", line 343, in __call__\n    fn(*args, **kw)\n\n  File \"/cvmfs/sw.lsst.eu/linux-x86_64/lsst_distrib/w_2022_36/conda/envs/lsst-scipipe-4.1.0/lib/python3.10/site-packages/sqlalchemy/engine/create.py\", line 658, in on_connect\n    do_on_connect(dbapi_connection)\n\n  File \"/cvmfs/sw.lsst.eu/linux-x86_64/lsst_distrib/w_2022_36/conda/envs/lsst-scipipe-4.1.0/lib/python3.10/site-packages/sqlalchemy/dialects/postgresql/psycopg2.py\", line 950, in on_connect\n    fn(conn)\n\n  File \"/cvmfs/sw.lsst.eu/linux-x86_64/lsst_distrib/w_2022_36/conda/envs/lsst-scipipe-4.1.0/lib/python3.10/site-packages/sqlalchemy/dialects/postgresql/psycopg2.py\", line 923, in on_connect\n    hstore_oids = self._hstore_oids(conn)\n\n  File \"/cvmfs/sw.lsst.eu/linux-x86_64/lsst_distrib/w_2022_36/conda/envs/lsst-scipipe-4.1.0/lib/python3.10/site-packages/sqlalchemy/util/langhelpers.py\", line 1134, in oneshot\n    result = fn(self, *args, **kw)\n\n  File \"/cvmfs/sw.lsst.eu/linux-x86_64/lsst_distrib/w_2022_36/conda/envs/lsst-scipipe-4.1.0/lib/python3.10/site-packages/sqlalchemy/dialects/postgresql/psycopg2.py\", line 1007, in _hstore_oids\n    oids = extras.HstoreAdapter.get_oids(conn)\n\n  File \"/cvmfs/sw.lsst.eu/linux-x86_64/lsst_distrib/w_2022_36/conda/envs/lsst-scipipe-4.1.0/lib/python3.10/site-packages/psycopg2/extras.py\", line 911, in get_oids\n    curs.execute(f\"\"\"SELECT t.oid, {typarray}\n\nsqlalchemy.exc.OperationalError: (psycopg2.OperationalError) query_wait_timeout\nSSL connection has been closed unexpectedly\n\n(Background on this error at: https://sqlalche.me/e/14/e3q8)\n", "MDC": {}}
{"name": "lsst.daf.butler._butler", "asctime": "2022-09-06T23:17:54.495445+00:00", "message": "Failed to instantiate Butler from config file:///sdf/group/rubin/repo/main_20220411/butler.yaml.", "levelno": 40, "levelname": "ERROR", "filename": "_butler.py", "pathname": "/cvmfs/sw.lsst.eu/linux-x86_64/lsst_distrib/w_2022_36/conda/envs/lsst-scipipe-4.1.0/share/eups/Linux64/daf_butler/g3ee7dd65e6+24e5aa5155/python/lsst/daf/butler/_butler.py", "lineno": 295, "funcName": "__init__", "process": 12567, "processName": "MainProcess", "MDC": {}}
{"name": "lsst.daf.butler.cli.utils", "asctime": "2022-09-06T23:17:54.497154+00:00", "message": "Caught an exception, details are in traceback:", "levelno": 40, "levelname": "ERROR", "filename": "utils.py", "pathname": "/cvmfs/sw.lsst.eu/linux-x86_64/lsst_distrib/w_2022_36/conda/envs/lsst-scipipe-4.1.0/share/eups/Linux64/daf_butler/g3ee7dd65e6+24e5aa5155/python/lsst/daf/butler/cli/utils.py", "lineno": 1093, "funcName": "inner", "process": 12567, "processName": "MainProcess", "exc_info": "Traceback (most recent call last):\n\n  File \"/cvmfs/sw.lsst.eu/linux-x86_64/lsst_distrib/w_2022_36/conda/envs/lsst-scipipe-4.1.0/lib/python3.10/site-packages/sqlalchemy/engine/base.py\", line 3361, in _wrap_pool_connect\n    return fn()\n\n  File \"/cvmfs/sw.lsst.eu/linux-x86_64/lsst_distrib/w_2022_36/conda/envs/lsst-scipipe-4.1.0/lib/python3.10/site-packages/sqlalchemy/pool/base.py\", line 310, in connect\n    return _ConnectionFairy._checkout(self)\n\n  File \"/cvmfs/sw.lsst.eu/linux-x86_64/lsst_distrib/w_2022_36/conda/envs/lsst-scipipe-4.1.0/lib/python3.10/site-packages/sqlalchemy/pool/base.py\", line 868, in _checkout\n    fairy = _ConnectionRecord.checkout(pool)\n\n  File \"/cvmfs/sw.lsst.eu/linux-x86_64/lsst_distrib/w_2022_36/conda/envs/lsst-scipipe-4.1.0/lib/python3.10/site-packages/sqlalchemy/pool/base.py\", line 476, in checkout\n    rec = pool._do_get()\n\n  File \"/cvmfs/sw.lsst.eu/linux-x86_64/lsst_distrib/w_2022_36/conda/envs/lsst-scipipe-4.1.0/lib/python3.10/site-packages/sqlalchemy/pool/impl.py\", line 145, in _do_get\n    with util.safe_reraise():\n\n  File \"/cvmfs/sw.lsst.eu/linux-x86_64/lsst_distrib/w_2022_36/conda/envs/lsst-scipipe-4.1.0/lib/python3.10/site-packages/sqlalchemy/util/langhelpers.py\", line 70, in __exit__\n    compat.raise_(\n\n  File \"/cvmfs/sw.lsst.eu/linux-x86_64/lsst_distrib/w_2022_36/conda/envs/lsst-scipipe-4.1.0/lib/python3.10/site-packages/sqlalchemy/util/compat.py\", line 208, in raise_\n    raise exception\n\n  File \"/cvmfs/sw.lsst.eu/linux-x86_64/lsst_distrib/w_2022_36/conda/envs/lsst-scipipe-4.1.0/lib/python3.10/site-packages/sqlalchemy/pool/impl.py\", line 143, in _do_get\n    return self._create_connection()\n\n  File \"/cvmfs/sw.lsst.eu/linux-x86_64/lsst_distrib/w_2022_36/conda/envs/lsst-scipipe-4.1.0/lib/python3.10/site-packages/sqlalchemy/pool/base.py\", line 256, in _create_connection\n    return _ConnectionRecord(self)\n\n  File \"/cvmfs/sw.lsst.eu/linux-x86_64/lsst_distrib/w_2022_36/conda/envs/lsst-scipipe-4.1.0/lib/python3.10/site-packages/sqlalchemy/pool/base.py\", line 371, in __init__\n    self.__connect()\n\n  File \"/cvmfs/sw.lsst.eu/linux-x86_64/lsst_distrib/w_2022_36/conda/envs/lsst-scipipe-4.1.0/lib/python3.10/site-packages/sqlalchemy/pool/base.py\", line 679, in __connect\n    )._exec_w_sync_on_first_run(self.dbapi_connection, self)\n\n  File \"/cvmfs/sw.lsst.eu/linux-x86_64/lsst_distrib/w_2022_36/conda/envs/lsst-scipipe-4.1.0/lib/python3.10/site-packages/sqlalchemy/event/attr.py\", line 329, in _exec_w_sync_on_first_run\n    self(*args, **kw)\n\n  File \"/cvmfs/sw.lsst.eu/linux-x86_64/lsst_distrib/w_2022_36/conda/envs/lsst-scipipe-4.1.0/lib/python3.10/site-packages/sqlalchemy/event/attr.py\", line 343, in __call__\n    fn(*args, **kw)\n\n  File \"/cvmfs/sw.lsst.eu/linux-x86_64/lsst_distrib/w_2022_36/conda/envs/lsst-scipipe-4.1.0/lib/python3.10/site-packages/sqlalchemy/engine/create.py\", line 658, in on_connect\n    do_on_connect(dbapi_connection)\n\n  File \"/cvmfs/sw.lsst.eu/linux-x86_64/lsst_distrib/w_2022_36/conda/envs/lsst-scipipe-4.1.0/lib/python3.10/site-packages/sqlalchemy/dialects/postgresql/psycopg2.py\", line 950, in on_connect\n    fn(conn)\n\n  File \"/cvmfs/sw.lsst.eu/linux-x86_64/lsst_distrib/w_2022_36/conda/envs/lsst-scipipe-4.1.0/lib/python3.10/site-packages/sqlalchemy/dialects/postgresql/psycopg2.py\", line 923, in on_connect\n    hstore_oids = self._hstore_oids(conn)\n\n  File \"/cvmfs/sw.lsst.eu/linux-x86_64/lsst_distrib/w_2022_36/conda/envs/lsst-scipipe-4.1.0/lib/python3.10/site-packages/sqlalchemy/util/langhelpers.py\", line 1134, in oneshot\n    result = fn(self, *args, **kw)\n\n  File \"/cvmfs/sw.lsst.eu/linux-x86_64/lsst_distrib/w_2022_36/conda/envs/lsst-scipipe-4.1.0/lib/python3.10/site-packages/sqlalchemy/dialects/postgresql/psycopg2.py\", line 1007, in _hstore_oids\n    oids = extras.HstoreAdapter.get_oids(conn)\n\n  File \"/cvmfs/sw.lsst.eu/linux-x86_64/lsst_distrib/w_2022_36/conda/envs/lsst-scipipe-4.1.0/lib/python3.10/site-packages/psycopg2/extras.py\", line 911, in get_oids\n    curs.execute(f\"\"\"SELECT t.oid, {typarray}\n\npsycopg2.OperationalError: query_wait_timeout\nSSL connection has been closed unexpectedly\n\n\n\nThe above exception was the direct cause of the following exception:\n\n\nTraceback (most recent call last):\n\n  File \"/cvmfs/sw.lsst.eu/linux-x86_64/lsst_distrib/w_2022_36/conda/envs/lsst-scipipe-4.1.0/share/eups/Linux64/ctrl_mpexec/g5106228df7+1629eaad64/python/lsst/ctrl/mpexec/cli/cmd/commands.py\", line 140, in qgraph\n    script.qgraph(pipelineObj=pipeline, **kwargs, show=show)\n\n  File \"/cvmfs/sw.lsst.eu/linux-x86_64/lsst_distrib/w_2022_36/conda/envs/lsst-scipipe-4.1.0/share/eups/Linux64/ctrl_mpexec/g5106228df7+1629eaad64/python/lsst/ctrl/mpexec/cli/script/qgraph.py\", line 196, in qgraph\n    qgraph = f.makeGraph(pipelineObj, args)\n\n  File \"/cvmfs/sw.lsst.eu/linux-x86_64/lsst_distrib/w_2022_36/conda/envs/lsst-scipipe-4.1.0/share/eups/Linux64/ctrl_mpexec/g5106228df7+1629eaad64/python/lsst/ctrl/mpexec/cmdLineFwk.py\", line 525, in makeGraph\n    butler, collections, run = _ButlerFactory.makeButlerAndCollections(args)\n\n  File \"/cvmfs/sw.lsst.eu/linux-x86_64/lsst_distrib/w_2022_36/conda/envs/lsst-scipipe-4.1.0/share/eups/Linux64/ctrl_mpexec/g5106228df7+1629eaad64/python/lsst/ctrl/mpexec/cmdLineFwk.py\", line 347, in makeButlerAndCollections\n    butler, inputs, self = cls._makeReadParts(args)\n\n  File \"/cvmfs/sw.lsst.eu/linux-x86_64/lsst_distrib/w_2022_36/conda/envs/lsst-scipipe-4.1.0/share/eups/Linux64/ctrl_mpexec/g5106228df7+1629eaad64/python/lsst/ctrl/mpexec/cmdLineFwk.py\", line 282, in _makeReadParts\n    butler = Butler(args.butler_config, writeable=False)\n\n  File \"/cvmfs/sw.lsst.eu/linux-x86_64/lsst_distrib/w_2022_36/conda/envs/lsst-scipipe-4.1.0/share/eups/Linux64/daf_butler/g3ee7dd65e6+24e5aa5155/python/lsst/daf/butler/_butler.py\", line 281, in __init__\n    self.registry = Registry.fromConfig(\n\n  File \"/cvmfs/sw.lsst.eu/linux-x86_64/lsst_distrib/w_2022_36/conda/envs/lsst-scipipe-4.1.0/share/eups/Linux64/daf_butler/g3ee7dd65e6+24e5aa5155/python/lsst/daf/butler/registry/_registry.py\", line 230, in fromConfig\n    return registry_cls.fromConfig(config, butlerRoot, writeable, defaults)\n\n  File \"/cvmfs/sw.lsst.eu/linux-x86_64/lsst_distrib/w_2022_36/conda/envs/lsst-scipipe-4.1.0/share/eups/Linux64/daf_butler/g3ee7dd65e6+24e5aa5155/python/lsst/daf/butler/registries/sql.py\", line 188, in fromConfig\n    database = DatabaseClass.fromUri(\n\n  File \"/cvmfs/sw.lsst.eu/linux-x86_64/lsst_distrib/w_2022_36/conda/envs/lsst-scipipe-4.1.0/share/eups/Linux64/daf_butler/g3ee7dd65e6+24e5aa5155/python/lsst/daf/butler/registry/interfaces/_database.py\", line 366, in fromUri\n    return cls.fromEngine(\n\n  File \"/cvmfs/sw.lsst.eu/linux-x86_64/lsst_distrib/w_2022_36/conda/envs/lsst-scipipe-4.1.0/share/eups/Linux64/daf_butler/g3ee7dd65e6+24e5aa5155/python/lsst/daf/butler/registry/databases/postgresql.py\", line 110, in fromEngine\n    return cls(engine=engine, origin=origin, namespace=namespace, writeable=writeable)\n\n  File \"/cvmfs/sw.lsst.eu/linux-x86_64/lsst_distrib/w_2022_36/conda/envs/lsst-scipipe-4.1.0/share/eups/Linux64/daf_butler/g3ee7dd65e6+24e5aa5155/python/lsst/daf/butler/registry/databases/postgresql.py\", line 76, in __init__\n    with engine.connect() as connection:\n\n  File \"/cvmfs/sw.lsst.eu/linux-x86_64/lsst_distrib/w_2022_36/conda/envs/lsst-scipipe-4.1.0/lib/python3.10/site-packages/sqlalchemy/engine/base.py\", line 3315, in connect\n    return self._connection_cls(self, close_with_result=close_with_result)\n\n  File \"/cvmfs/sw.lsst.eu/linux-x86_64/lsst_distrib/w_2022_36/conda/envs/lsst-scipipe-4.1.0/lib/python3.10/site-packages/sqlalchemy/engine/base.py\", line 96, in __init__\n    else engine.raw_connection()\n\n  File \"/cvmfs/sw.lsst.eu/linux-x86_64/lsst_distrib/w_2022_36/conda/envs/lsst-scipipe-4.1.0/lib/python3.10/site-packages/sqlalchemy/engine/base.py\", line 3394, in raw_connection\n    return self._wrap_pool_connect(self.pool.connect, _connection)\n\n  File \"/cvmfs/sw.lsst.eu/linux-x86_64/lsst_distrib/w_2022_36/conda/envs/lsst-scipipe-4.1.0/lib/python3.10/site-packages/sqlalchemy/engine/base.py\", line 3364, in _wrap_pool_connect\n    Connection._handle_dbapi_exception_noconnection(\n\n  File \"/cvmfs/sw.lsst.eu/linux-x86_64/lsst_distrib/w_2022_36/conda/envs/lsst-scipipe-4.1.0/lib/python3.10/site-packages/sqlalchemy/engine/base.py\", line 2198, in _handle_dbapi_exception_noconnection\n    util.raise_(\n\n  File \"/cvmfs/sw.lsst.eu/linux-x86_64/lsst_distrib/w_2022_36/conda/envs/lsst-scipipe-4.1.0/lib/python3.10/site-packages/sqlalchemy/util/compat.py\", line 208, in raise_\n    raise exception\n\n  File \"/cvmfs/sw.lsst.eu/linux-x86_64/lsst_distrib/w_2022_36/conda/envs/lsst-scipipe-4.1.0/lib/python3.10/site-packages/sqlalchemy/engine/base.py\", line 3361, in _wrap_pool_connect\n    return fn()\n\n  File \"/cvmfs/sw.lsst.eu/linux-x86_64/lsst_distrib/w_2022_36/conda/envs/lsst-scipipe-4.1.0/lib/python3.10/site-packages/sqlalchemy/pool/base.py\", line 310, in connect\n    return _ConnectionFairy._checkout(self)\n\n  File \"/cvmfs/sw.lsst.eu/linux-x86_64/lsst_distrib/w_2022_36/conda/envs/lsst-scipipe-4.1.0/lib/python3.10/site-packages/sqlalchemy/pool/base.py\", line 868, in _checkout\n    fairy = _ConnectionRecord.checkout(pool)\n\n  File \"/cvmfs/sw.lsst.eu/linux-x86_64/lsst_distrib/w_2022_36/conda/envs/lsst-scipipe-4.1.0/lib/python3.10/site-packages/sqlalchemy/pool/base.py\", line 476, in checkout\n    rec = pool._do_get()\n\n  File \"/cvmfs/sw.lsst.eu/linux-x86_64/lsst_distrib/w_2022_36/conda/envs/lsst-scipipe-4.1.0/lib/python3.10/site-packages/sqlalchemy/pool/impl.py\", line 145, in _do_get\n    with util.safe_reraise():\n\n  File \"/cvmfs/sw.lsst.eu/linux-x86_64/lsst_distrib/w_2022_36/conda/envs/lsst-scipipe-4.1.0/lib/python3.10/site-packages/sqlalchemy/util/langhelpers.py\", line 70, in __exit__\n    compat.raise_(\n\n  File \"/cvmfs/sw.lsst.eu/linux-x86_64/lsst_distrib/w_2022_36/conda/envs/lsst-scipipe-4.1.0/lib/python3.10/site-packages/sqlalchemy/util/compat.py\", line 208, in raise_\n    raise exception\n\n  File \"/cvmfs/sw.lsst.eu/linux-x86_64/lsst_distrib/w_2022_36/conda/envs/lsst-scipipe-4.1.0/lib/python3.10/site-packages/sqlalchemy/pool/impl.py\", line 143, in _do_get\n    return self._create_connection()\n\n  File \"/cvmfs/sw.lsst.eu/linux-x86_64/lsst_distrib/w_2022_36/conda/envs/lsst-scipipe-4.1.0/lib/python3.10/site-packages/sqlalchemy/pool/base.py\", line 256, in _create_connection\n    return _ConnectionRecord(self)\n\n  File \"/cvmfs/sw.lsst.eu/linux-x86_64/lsst_distrib/w_2022_36/conda/envs/lsst-scipipe-4.1.0/lib/python3.10/site-packages/sqlalchemy/pool/base.py\", line 371, in __init__\n    self.__connect()\n\n  File \"/cvmfs/sw.lsst.eu/linux-x86_64/lsst_distrib/w_2022_36/conda/envs/lsst-scipipe-4.1.0/lib/python3.10/site-packages/sqlalchemy/pool/base.py\", line 679, in __connect\n    )._exec_w_sync_on_first_run(self.dbapi_connection, self)\n\n  File \"/cvmfs/sw.lsst.eu/linux-x86_64/lsst_distrib/w_2022_36/conda/envs/lsst-scipipe-4.1.0/lib/python3.10/site-packages/sqlalchemy/event/attr.py\", line 329, in _exec_w_sync_on_first_run\n    self(*args, **kw)\n\n  File \"/cvmfs/sw.lsst.eu/linux-x86_64/lsst_distrib/w_2022_36/conda/envs/lsst-scipipe-4.1.0/lib/python3.10/site-packages/sqlalchemy/event/attr.py\", line 343, in __call__\n    fn(*args, **kw)\n\n  File \"/cvmfs/sw.lsst.eu/linux-x86_64/lsst_distrib/w_2022_36/conda/envs/lsst-scipipe-4.1.0/lib/python3.10/site-packages/sqlalchemy/engine/create.py\", line 658, in on_connect\n    do_on_connect(dbapi_connection)\n\n  File \"/cvmfs/sw.lsst.eu/linux-x86_64/lsst_distrib/w_2022_36/conda/envs/lsst-scipipe-4.1.0/lib/python3.10/site-packages/sqlalchemy/dialects/postgresql/psycopg2.py\", line 950, in on_connect\n    fn(conn)\n\n  File \"/cvmfs/sw.lsst.eu/linux-x86_64/lsst_distrib/w_2022_36/conda/envs/lsst-scipipe-4.1.0/lib/python3.10/site-packages/sqlalchemy/dialects/postgresql/psycopg2.py\", line 923, in on_connect\n    hstore_oids = self._hstore_oids(conn)\n\n  File \"/cvmfs/sw.lsst.eu/linux-x86_64/lsst_distrib/w_2022_36/conda/envs/lsst-scipipe-4.1.0/lib/python3.10/site-packages/sqlalchemy/util/langhelpers.py\", line 1134, in oneshot\n    result = fn(self, *args, **kw)\n\n  File \"/cvmfs/sw.lsst.eu/linux-x86_64/lsst_distrib/w_2022_36/conda/envs/lsst-scipipe-4.1.0/lib/python3.10/site-packages/sqlalchemy/dialects/postgresql/psycopg2.py\", line 1007, in _hstore_oids\n    oids = extras.HstoreAdapter.get_oids(conn)\n\n  File \"/cvmfs/sw.lsst.eu/linux-x86_64/lsst_distrib/w_2022_36/conda/envs/lsst-scipipe-4.1.0/lib/python3.10/site-packages/psycopg2/extras.py\", line 911, in get_oids\n    curs.execute(f\"\"\"SELECT t.oid, {typarray}\n\nsqlalchemy.exc.OperationalError: (psycopg2.OperationalError) query_wait_timeout\nSSL connection has been closed unexpectedly\n\n(Background on this error at: https://sqlalche.me/e/14/e3q8)\n", "MDC": {}}
{"name": "lsst.daf.butler._butler", "asctime": "2022-09-06T23:21:05.829723+00:00", "message": "Failed to instantiate Butler from config file:///sdf/group/rubin/repo/main_20220411/butler.yaml.", "levelno": 40, "levelname": "ERROR", "filename": "_butler.py", "pathname": "/cvmfs/sw.lsst.eu/linux-x86_64/lsst_distrib/w_2022_36/conda/envs/lsst-scipipe-4.1.0/share/eups/Linux64/daf_butler/g3ee7dd65e6+24e5aa5155/python/lsst/daf/butler/_butler.py", "lineno": 295, "funcName": "__init__", "process": 13116, "processName": "MainProcess", "MDC": {}}
{"name": "lsst.daf.butler.cli.utils", "asctime": "2022-09-06T23:21:05.831376+00:00", "message": "Caught an exception, details are in traceback:", "levelno": 40, "levelname": "ERROR", "filename": "utils.py", "pathname": "/cvmfs/sw.lsst.eu/linux-x86_64/lsst_distrib/w_2022_36/conda/envs/lsst-scipipe-4.1.0/share/eups/Linux64/daf_butler/g3ee7dd65e6+24e5aa5155/python/lsst/daf/butler/cli/utils.py", "lineno": 1093, "funcName": "inner", "process": 13116, "processName": "MainProcess", "exc_info": "Traceback (most recent call last):\n\n  File \"/cvmfs/sw.lsst.eu/linux-x86_64/lsst_distrib/w_2022_36/conda/envs/lsst-scipipe-4.1.0/lib/python3.10/site-packages/sqlalchemy/engine/base.py\", line 3361, in _wrap_pool_connect\n    return fn()\n\n  File \"/cvmfs/sw.lsst.eu/linux-x86_64/lsst_distrib/w_2022_36/conda/envs/lsst-scipipe-4.1.0/lib/python3.10/site-packages/sqlalchemy/pool/base.py\", line 310, in connect\n    return _ConnectionFairy._checkout(self)\n\n  File \"/cvmfs/sw.lsst.eu/linux-x86_64/lsst_distrib/w_2022_36/conda/envs/lsst-scipipe-4.1.0/lib/python3.10/site-packages/sqlalchemy/pool/base.py\", line 868, in _checkout\n    fairy = _ConnectionRecord.checkout(pool)\n\n  File \"/cvmfs/sw.lsst.eu/linux-x86_64/lsst_distrib/w_2022_36/conda/envs/lsst-scipipe-4.1.0/lib/python3.10/site-packages/sqlalchemy/pool/base.py\", line 476, in checkout\n    rec = pool._do_get()\n\n  File \"/cvmfs/sw.lsst.eu/linux-x86_64/lsst_distrib/w_2022_36/conda/envs/lsst-scipipe-4.1.0/lib/python3.10/site-packages/sqlalchemy/pool/impl.py\", line 145, in _do_get\n    with util.safe_reraise():\n\n  File \"/cvmfs/sw.lsst.eu/linux-x86_64/lsst_distrib/w_2022_36/conda/envs/lsst-scipipe-4.1.0/lib/python3.10/site-packages/sqlalchemy/util/langhelpers.py\", line 70, in __exit__\n    compat.raise_(\n\n  File \"/cvmfs/sw.lsst.eu/linux-x86_64/lsst_distrib/w_2022_36/conda/envs/lsst-scipipe-4.1.0/lib/python3.10/site-packages/sqlalchemy/util/compat.py\", line 208, in raise_\n    raise exception\n\n  File \"/cvmfs/sw.lsst.eu/linux-x86_64/lsst_distrib/w_2022_36/conda/envs/lsst-scipipe-4.1.0/lib/python3.10/site-packages/sqlalchemy/pool/impl.py\", line 143, in _do_get\n    return self._create_connection()\n\n  File \"/cvmfs/sw.lsst.eu/linux-x86_64/lsst_distrib/w_2022_36/conda/envs/lsst-scipipe-4.1.0/lib/python3.10/site-packages/sqlalchemy/pool/base.py\", line 256, in _create_connection\n    return _ConnectionRecord(self)\n\n  File \"/cvmfs/sw.lsst.eu/linux-x86_64/lsst_distrib/w_2022_36/conda/envs/lsst-scipipe-4.1.0/lib/python3.10/site-packages/sqlalchemy/pool/base.py\", line 371, in __init__\n    self.__connect()\n\n  File \"/cvmfs/sw.lsst.eu/linux-x86_64/lsst_distrib/w_2022_36/conda/envs/lsst-scipipe-4.1.0/lib/python3.10/site-packages/sqlalchemy/pool/base.py\", line 679, in __connect\n    )._exec_w_sync_on_first_run(self.dbapi_connection, self)\n\n  File \"/cvmfs/sw.lsst.eu/linux-x86_64/lsst_distrib/w_2022_36/conda/envs/lsst-scipipe-4.1.0/lib/python3.10/site-packages/sqlalchemy/event/attr.py\", line 329, in _exec_w_sync_on_first_run\n    self(*args, **kw)\n\n  File \"/cvmfs/sw.lsst.eu/linux-x86_64/lsst_distrib/w_2022_36/conda/envs/lsst-scipipe-4.1.0/lib/python3.10/site-packages/sqlalchemy/event/attr.py\", line 343, in __call__\n    fn(*args, **kw)\n\n  File \"/cvmfs/sw.lsst.eu/linux-x86_64/lsst_distrib/w_2022_36/conda/envs/lsst-scipipe-4.1.0/lib/python3.10/site-packages/sqlalchemy/engine/create.py\", line 658, in on_connect\n    do_on_connect(dbapi_connection)\n\n  File \"/cvmfs/sw.lsst.eu/linux-x86_64/lsst_distrib/w_2022_36/conda/envs/lsst-scipipe-4.1.0/lib/python3.10/site-packages/sqlalchemy/dialects/postgresql/psycopg2.py\", line 950, in on_connect\n    fn(conn)\n\n  File \"/cvmfs/sw.lsst.eu/linux-x86_64/lsst_distrib/w_2022_36/conda/envs/lsst-scipipe-4.1.0/lib/python3.10/site-packages/sqlalchemy/dialects/postgresql/psycopg2.py\", line 923, in on_connect\n    hstore_oids = self._hstore_oids(conn)\n\n  File \"/cvmfs/sw.lsst.eu/linux-x86_64/lsst_distrib/w_2022_36/conda/envs/lsst-scipipe-4.1.0/lib/python3.10/site-packages/sqlalchemy/util/langhelpers.py\", line 1134, in oneshot\n    result = fn(self, *args, **kw)\n\n  File \"/cvmfs/sw.lsst.eu/linux-x86_64/lsst_distrib/w_2022_36/conda/envs/lsst-scipipe-4.1.0/lib/python3.10/site-packages/sqlalchemy/dialects/postgresql/psycopg2.py\", line 1007, in _hstore_oids\n    oids = extras.HstoreAdapter.get_oids(conn)\n\n  File \"/cvmfs/sw.lsst.eu/linux-x86_64/lsst_distrib/w_2022_36/conda/envs/lsst-scipipe-4.1.0/lib/python3.10/site-packages/psycopg2/extras.py\", line 911, in get_oids\n    curs.execute(f\"\"\"SELECT t.oid, {typarray}\n\npsycopg2.OperationalError: query_wait_timeout\nSSL connection has been closed unexpectedly\n\n\n\nThe above exception was the direct cause of the following exception:\n\n\nTraceback (most recent call last):\n\n  File \"/cvmfs/sw.lsst.eu/linux-x86_64/lsst_distrib/w_2022_36/conda/envs/lsst-scipipe-4.1.0/share/eups/Linux64/ctrl_mpexec/g5106228df7+1629eaad64/python/lsst/ctrl/mpexec/cli/cmd/commands.py\", line 140, in qgraph\n    script.qgraph(pipelineObj=pipeline, **kwargs, show=show)\n\n  File \"/cvmfs/sw.lsst.eu/linux-x86_64/lsst_distrib/w_2022_36/conda/envs/lsst-scipipe-4.1.0/share/eups/Linux64/ctrl_mpexec/g5106228df7+1629eaad64/python/lsst/ctrl/mpexec/cli/script/qgraph.py\", line 196, in qgraph\n    qgraph = f.makeGraph(pipelineObj, args)\n\n  File \"/cvmfs/sw.lsst.eu/linux-x86_64/lsst_distrib/w_2022_36/conda/envs/lsst-scipipe-4.1.0/share/eups/Linux64/ctrl_mpexec/g5106228df7+1629eaad64/python/lsst/ctrl/mpexec/cmdLineFwk.py\", line 525, in makeGraph\n    butler, collections, run = _ButlerFactory.makeButlerAndCollections(args)\n\n  File \"/cvmfs/sw.lsst.eu/linux-x86_64/lsst_distrib/w_2022_36/conda/envs/lsst-scipipe-4.1.0/share/eups/Linux64/ctrl_mpexec/g5106228df7+1629eaad64/python/lsst/ctrl/mpexec/cmdLineFwk.py\", line 347, in makeButlerAndCollections\n    butler, inputs, self = cls._makeReadParts(args)\n\n  File \"/cvmfs/sw.lsst.eu/linux-x86_64/lsst_distrib/w_2022_36/conda/envs/lsst-scipipe-4.1.0/share/eups/Linux64/ctrl_mpexec/g5106228df7+1629eaad64/python/lsst/ctrl/mpexec/cmdLineFwk.py\", line 282, in _makeReadParts\n    butler = Butler(args.butler_config, writeable=False)\n\n  File \"/cvmfs/sw.lsst.eu/linux-x86_64/lsst_distrib/w_2022_36/conda/envs/lsst-scipipe-4.1.0/share/eups/Linux64/daf_butler/g3ee7dd65e6+24e5aa5155/python/lsst/daf/butler/_butler.py\", line 281, in __init__\n    self.registry = Registry.fromConfig(\n\n  File \"/cvmfs/sw.lsst.eu/linux-x86_64/lsst_distrib/w_2022_36/conda/envs/lsst-scipipe-4.1.0/share/eups/Linux64/daf_butler/g3ee7dd65e6+24e5aa5155/python/lsst/daf/butler/registry/_registry.py\", line 230, in fromConfig\n    return registry_cls.fromConfig(config, butlerRoot, writeable, defaults)\n\n  File \"/cvmfs/sw.lsst.eu/linux-x86_64/lsst_distrib/w_2022_36/conda/envs/lsst-scipipe-4.1.0/share/eups/Linux64/daf_butler/g3ee7dd65e6+24e5aa5155/python/lsst/daf/butler/registries/sql.py\", line 188, in fromConfig\n    database = DatabaseClass.fromUri(\n\n  File \"/cvmfs/sw.lsst.eu/linux-x86_64/lsst_distrib/w_2022_36/conda/envs/lsst-scipipe-4.1.0/share/eups/Linux64/daf_butler/g3ee7dd65e6+24e5aa5155/python/lsst/daf/butler/registry/interfaces/_database.py\", line 366, in fromUri\n    return cls.fromEngine(\n\n  File \"/cvmfs/sw.lsst.eu/linux-x86_64/lsst_distrib/w_2022_36/conda/envs/lsst-scipipe-4.1.0/share/eups/Linux64/daf_butler/g3ee7dd65e6+24e5aa5155/python/lsst/daf/butler/registry/databases/postgresql.py\", line 110, in fromEngine\n    return cls(engine=engine, origin=origin, namespace=namespace, writeable=writeable)\n\n  File \"/cvmfs/sw.lsst.eu/linux-x86_64/lsst_distrib/w_2022_36/conda/envs/lsst-scipipe-4.1.0/share/eups/Linux64/daf_butler/g3ee7dd65e6+24e5aa5155/python/lsst/daf/butler/registry/databases/postgresql.py\", line 76, in __init__\n    with engine.connect() as connection:\n\n  File \"/cvmfs/sw.lsst.eu/linux-x86_64/lsst_distrib/w_2022_36/conda/envs/lsst-scipipe-4.1.0/lib/python3.10/site-packages/sqlalchemy/engine/base.py\", line 3315, in connect\n    return self._connection_cls(self, close_with_result=close_with_result)\n\n  File \"/cvmfs/sw.lsst.eu/linux-x86_64/lsst_distrib/w_2022_36/conda/envs/lsst-scipipe-4.1.0/lib/python3.10/site-packages/sqlalchemy/engine/base.py\", line 96, in __init__\n    else engine.raw_connection()\n\n  File \"/cvmfs/sw.lsst.eu/linux-x86_64/lsst_distrib/w_2022_36/conda/envs/lsst-scipipe-4.1.0/lib/python3.10/site-packages/sqlalchemy/engine/base.py\", line 3394, in raw_connection\n    return self._wrap_pool_connect(self.pool.connect, _connection)\n\n  File \"/cvmfs/sw.lsst.eu/linux-x86_64/lsst_distrib/w_2022_36/conda/envs/lsst-scipipe-4.1.0/lib/python3.10/site-packages/sqlalchemy/engine/base.py\", line 3364, in _wrap_pool_connect\n    Connection._handle_dbapi_exception_noconnection(\n\n  File \"/cvmfs/sw.lsst.eu/linux-x86_64/lsst_distrib/w_2022_36/conda/envs/lsst-scipipe-4.1.0/lib/python3.10/site-packages/sqlalchemy/engine/base.py\", line 2198, in _handle_dbapi_exception_noconnection\n    util.raise_(\n\n  File \"/cvmfs/sw.lsst.eu/linux-x86_64/lsst_distrib/w_2022_36/conda/envs/lsst-scipipe-4.1.0/lib/python3.10/site-packages/sqlalchemy/util/compat.py\", line 208, in raise_\n    raise exception\n\n  File \"/cvmfs/sw.lsst.eu/linux-x86_64/lsst_distrib/w_2022_36/conda/envs/lsst-scipipe-4.1.0/lib/python3.10/site-packages/sqlalchemy/engine/base.py\", line 3361, in _wrap_pool_connect\n    return fn()\n\n  File \"/cvmfs/sw.lsst.eu/linux-x86_64/lsst_distrib/w_2022_36/conda/envs/lsst-scipipe-4.1.0/lib/python3.10/site-packages/sqlalchemy/pool/base.py\", line 310, in connect\n    return _ConnectionFairy._checkout(self)\n\n  File \"/cvmfs/sw.lsst.eu/linux-x86_64/lsst_distrib/w_2022_36/conda/envs/lsst-scipipe-4.1.0/lib/python3.10/site-packages/sqlalchemy/pool/base.py\", line 868, in _checkout\n    fairy = _ConnectionRecord.checkout(pool)\n\n  File \"/cvmfs/sw.lsst.eu/linux-x86_64/lsst_distrib/w_2022_36/conda/envs/lsst-scipipe-4.1.0/lib/python3.10/site-packages/sqlalchemy/pool/base.py\", line 476, in checkout\n    rec = pool._do_get()\n\n  File \"/cvmfs/sw.lsst.eu/linux-x86_64/lsst_distrib/w_2022_36/conda/envs/lsst-scipipe-4.1.0/lib/python3.10/site-packages/sqlalchemy/pool/impl.py\", line 145, in _do_get\n    with util.safe_reraise():\n\n  File \"/cvmfs/sw.lsst.eu/linux-x86_64/lsst_distrib/w_2022_36/conda/envs/lsst-scipipe-4.1.0/lib/python3.10/site-packages/sqlalchemy/util/langhelpers.py\", line 70, in __exit__\n    compat.raise_(\n\n  File \"/cvmfs/sw.lsst.eu/linux-x86_64/lsst_distrib/w_2022_36/conda/envs/lsst-scipipe-4.1.0/lib/python3.10/site-packages/sqlalchemy/util/compat.py\", line 208, in raise_\n    raise exception\n\n  File \"/cvmfs/sw.lsst.eu/linux-x86_64/lsst_distrib/w_2022_36/conda/envs/lsst-scipipe-4.1.0/lib/python3.10/site-packages/sqlalchemy/pool/impl.py\", line 143, in _do_get\n    return self._create_connection()\n\n  File \"/cvmfs/sw.lsst.eu/linux-x86_64/lsst_distrib/w_2022_36/conda/envs/lsst-scipipe-4.1.0/lib/python3.10/site-packages/sqlalchemy/pool/base.py\", line 256, in _create_connection\n    return _ConnectionRecord(self)\n\n  File \"/cvmfs/sw.lsst.eu/linux-x86_64/lsst_distrib/w_2022_36/conda/envs/lsst-scipipe-4.1.0/lib/python3.10/site-packages/sqlalchemy/pool/base.py\", line 371, in __init__\n    self.__connect()\n\n  File \"/cvmfs/sw.lsst.eu/linux-x86_64/lsst_distrib/w_2022_36/conda/envs/lsst-scipipe-4.1.0/lib/python3.10/site-packages/sqlalchemy/pool/base.py\", line 679, in __connect\n    )._exec_w_sync_on_first_run(self.dbapi_connection, self)\n\n  File \"/cvmfs/sw.lsst.eu/linux-x86_64/lsst_distrib/w_2022_36/conda/envs/lsst-scipipe-4.1.0/lib/python3.10/site-packages/sqlalchemy/event/attr.py\", line 329, in _exec_w_sync_on_first_run\n    self(*args, **kw)\n\n  File \"/cvmfs/sw.lsst.eu/linux-x86_64/lsst_distrib/w_2022_36/conda/envs/lsst-scipipe-4.1.0/lib/python3.10/site-packages/sqlalchemy/event/attr.py\", line 343, in __call__\n    fn(*args, **kw)\n\n  File \"/cvmfs/sw.lsst.eu/linux-x86_64/lsst_distrib/w_2022_36/conda/envs/lsst-scipipe-4.1.0/lib/python3.10/site-packages/sqlalchemy/engine/create.py\", line 658, in on_connect\n    do_on_connect(dbapi_connection)\n\n  File \"/cvmfs/sw.lsst.eu/linux-x86_64/lsst_distrib/w_2022_36/conda/envs/lsst-scipipe-4.1.0/lib/python3.10/site-packages/sqlalchemy/dialects/postgresql/psycopg2.py\", line 950, in on_connect\n    fn(conn)\n\n  File \"/cvmfs/sw.lsst.eu/linux-x86_64/lsst_distrib/w_2022_36/conda/envs/lsst-scipipe-4.1.0/lib/python3.10/site-packages/sqlalchemy/dialects/postgresql/psycopg2.py\", line 923, in on_connect\n    hstore_oids = self._hstore_oids(conn)\n\n  File \"/cvmfs/sw.lsst.eu/linux-x86_64/lsst_distrib/w_2022_36/conda/envs/lsst-scipipe-4.1.0/lib/python3.10/site-packages/sqlalchemy/util/langhelpers.py\", line 1134, in oneshot\n    result = fn(self, *args, **kw)\n\n  File \"/cvmfs/sw.lsst.eu/linux-x86_64/lsst_distrib/w_2022_36/conda/envs/lsst-scipipe-4.1.0/lib/python3.10/site-packages/sqlalchemy/dialects/postgresql/psycopg2.py\", line 1007, in _hstore_oids\n    oids = extras.HstoreAdapter.get_oids(conn)\n\n  File \"/cvmfs/sw.lsst.eu/linux-x86_64/lsst_distrib/w_2022_36/conda/envs/lsst-scipipe-4.1.0/lib/python3.10/site-packages/psycopg2/extras.py\", line 911, in get_oids\n    curs.execute(f\"\"\"SELECT t.oid, {typarray}\n\nsqlalchemy.exc.OperationalError: (psycopg2.OperationalError) query_wait_timeout\nSSL connection has been closed unexpectedly\n\n(Background on this error at: https://sqlalche.me/e/14/e3q8)\n", "MDC": {}}
{"name": "py.warnings", "asctime": "2022-09-06T23:23:06.033839+00:00", "message": "/cvmfs/sw.lsst.eu/linux-x86_64/lsst_distrib/w_2022_36/conda/envs/lsst-scipipe-4.1.0/share/eups/Linux64/pex_config/g71c1dbb2b5+34f28eb435/python/lsst/pex/config/configurableField.py:79: FutureWarning: Call to deprecated class LoadIndexedReferenceObjectsConfig. (This config is no longer used; it will be removed after v25. Please use LoadReferenceObjectsConfig instead.) -- Deprecated since version v25.0.\n  value = self._ConfigClass(__name=name, __at=at, __label=label, **storage)\n", "levelno": 30, "levelname": "WARNING", "filename": "warnings.py", "pathname": "/cvmfs/sw.lsst.eu/linux-x86_64/lsst_distrib/w_2022_36/conda/envs/lsst-scipipe-4.1.0/lib/python3.10/warnings.py", "lineno": 109, "funcName": "_showwarnmsg", "process": 13965, "processName": "MainProcess", "MDC": {}}
{"name": "py.warnings", "asctime": "2022-09-06T23:23:06.035671+00:00", "message": "/cvmfs/sw.lsst.eu/linux-x86_64/lsst_distrib/w_2022_36/conda/envs/lsst-scipipe-4.1.0/share/eups/Linux64/pex_config/g71c1dbb2b5+34f28eb435/python/lsst/pex/config/configurableField.py:359: FutureWarning: Call to deprecated class LoadIndexedReferenceObjectsConfig. (This config is no longer used; it will be removed after v25. Please use LoadReferenceObjectsConfig instead.) -- Deprecated since version v25.0.\n  value = oldValue.ConfigClass()\n", "levelno": 30, "levelname": "WARNING", "filename": "warnings.py", "pathname": "/cvmfs/sw.lsst.eu/linux-x86_64/lsst_distrib/w_2022_36/conda/envs/lsst-scipipe-4.1.0/lib/python3.10/warnings.py", "lineno": 109, "funcName": "_showwarnmsg", "process": 13965, "processName": "MainProcess", "MDC": {}}
{"name": "lsst.ctrl.mpexec.cmdLineFwk", "asctime": "2022-09-06T23:38:52.964688+00:00", "message": "QuantumGraph contains 1770 quanta for 10 tasks, graph ID: '1662507522.3647742-13965'", "levelno": 20, "levelname": "INFO", "filename": "cmdLineFwk.py", "pathname": "/cvmfs/sw.lsst.eu/linux-x86_64/lsst_distrib/w_2022_36/conda/envs/lsst-scipipe-4.1.0/share/eups/Linux64/ctrl_mpexec/g5106228df7+1629eaad64/python/lsst/ctrl/mpexec/cmdLineFwk.py", "lineno": 581, "funcName": "makeGraph", "process": 13965, "processName": "MainProcess", "MDC": {}}
{"name": "py.warnings", "asctime": "2022-09-07T18:01:09.220249+00:00", "message": "/cvmfs/sw.lsst.eu/linux-x86_64/lsst_distrib/w_2022_36/conda/envs/lsst-scipipe-4.1.0/share/eups/Linux64/pex_config/g71c1dbb2b5+34f28eb435/python/lsst/pex/config/configurableField.py:79: FutureWarning: Call to deprecated class LoadIndexedReferenceObjectsConfig. (This config is no longer used; it will be removed after v25. Please use LoadReferenceObjectsConfig instead.) -- Deprecated since version v25.0.\n  value = self._ConfigClass(__name=name, __at=at, __label=label, **storage)\n", "levelno": 30, "levelname": "WARNING", "filename": "warnings.py", "pathname": "/cvmfs/sw.lsst.eu/linux-x86_64/lsst_distrib/w_2022_36/conda/envs/lsst-scipipe-4.1.0/lib/python3.10/warnings.py", "lineno": 109, "funcName": "_showwarnmsg", "process": 1277, "processName": "MainProcess", "MDC": {}}
{"name": "py.warnings", "asctime": "2022-09-07T18:01:09.250943+00:00", "message": "/cvmfs/sw.lsst.eu/linux-x86_64/lsst_distrib/w_2022_36/conda/envs/lsst-scipipe-4.1.0/share/eups/Linux64/pex_config/g71c1dbb2b5+34f28eb435/python/lsst/pex/config/configurableField.py:359: FutureWarning: Call to deprecated class LoadIndexedReferenceObjectsConfig. (This config is no longer used; it will be removed after v25. Please use LoadReferenceObjectsConfig instead.) -- Deprecated since version v25.0.\n  value = oldValue.ConfigClass()\n", "levelno": 30, "levelname": "WARNING", "filename": "warnings.py", "pathname": "/cvmfs/sw.lsst.eu/linux-x86_64/lsst_distrib/w_2022_36/conda/envs/lsst-scipipe-4.1.0/lib/python3.10/warnings.py", "lineno": 109, "funcName": "_showwarnmsg", "process": 1277, "processName": "MainProcess", "MDC": {}}
{"name": "lsst.ctrl.mpexec.cmdLineFwk", "asctime": "2022-09-07T18:17:04.040493+00:00", "message": "QuantumGraph contains 1770 quanta for 10 tasks, graph ID: '1662574613.8124826-1277'", "levelno": 20, "levelname": "INFO", "filename": "cmdLineFwk.py", "pathname": "/cvmfs/sw.lsst.eu/linux-x86_64/lsst_distrib/w_2022_36/conda/envs/lsst-scipipe-4.1.0/share/eups/Linux64/ctrl_mpexec/g5106228df7+1629eaad64/python/lsst/ctrl/mpexec/cmdLineFwk.py", "lineno": 581, "funcName": "makeGraph", "process": 1277, "processName": "MainProcess", "MDC": {}}
{"name": "py.warnings", "asctime": "2022-09-08T18:08:06.410080+00:00", "message": "/cvmfs/sw.lsst.eu/linux-x86_64/lsst_distrib/w_2022_36/conda/envs/lsst-scipipe-4.1.0/share/eups/Linux64/pex_config/g71c1dbb2b5+34f28eb435/python/lsst/pex/config/configurableField.py:79: FutureWarning: Call to deprecated class LoadIndexedReferenceObjectsConfig. (This config is no longer used; it will be removed after v25. Please use LoadReferenceObjectsConfig instead.) -- Deprecated since version v25.0.\n  value = self._ConfigClass(__name=name, __at=at, __label=label, **storage)\n", "levelno": 30, "levelname": "WARNING", "filename": "warnings.py", "pathname": "/cvmfs/sw.lsst.eu/linux-x86_64/lsst_distrib/w_2022_36/conda/envs/lsst-scipipe-4.1.0/lib/python3.10/warnings.py", "lineno": 109, "funcName": "_showwarnmsg", "process": 112139, "processName": "MainProcess", "MDC": {}}
{"name": "py.warnings", "asctime": "2022-09-08T18:08:06.440574+00:00", "message": "/cvmfs/sw.lsst.eu/linux-x86_64/lsst_distrib/w_2022_36/conda/envs/lsst-scipipe-4.1.0/share/eups/Linux64/pex_config/g71c1dbb2b5+34f28eb435/python/lsst/pex/config/configurableField.py:359: FutureWarning: Call to deprecated class LoadIndexedReferenceObjectsConfig. (This config is no longer used; it will be removed after v25. Please use LoadReferenceObjectsConfig instead.) -- Deprecated since version v25.0.\n  value = oldValue.ConfigClass()\n", "levelno": 30, "levelname": "WARNING", "filename": "warnings.py", "pathname": "/cvmfs/sw.lsst.eu/linux-x86_64/lsst_distrib/w_2022_36/conda/envs/lsst-scipipe-4.1.0/lib/python3.10/warnings.py", "lineno": 109, "funcName": "_showwarnmsg", "process": 112139, "processName": "MainProcess", "MDC": {}}
{"name": "lsst.ctrl.mpexec.cmdLineFwk", "asctime": "2022-09-08T18:11:04.645204+00:00", "message": "QuantumGraph contains 27 quanta for 10 tasks, graph ID: '1662660664.370684-112139'", "levelno": 20, "levelname": "INFO", "filename": "cmdLineFwk.py", "pathname": "/cvmfs/sw.lsst.eu/linux-x86_64/lsst_distrib/w_2022_36/conda/envs/lsst-scipipe-4.1.0/share/eups/Linux64/ctrl_mpexec/g5106228df7+1629eaad64/python/lsst/ctrl/mpexec/cmdLineFwk.py", "lineno": 581, "funcName": "makeGraph", "process": 112139, "processName": "MainProcess", "MDC": {}}
{"name": "py.warnings", "asctime": "2022-09-08T21:03:00.568710+00:00", "message": "/cvmfs/sw.lsst.eu/linux-x86_64/lsst_distrib/w_2022_36/conda/envs/lsst-scipipe-4.1.0/share/eups/Linux64/pipe_tasks/gafc8b9801c+ead7a49d6b/python/lsst/pipe/tasks/multiBand.py:243: UserWarning: MeasureMergedCoaddSourcesConnections.defaultTemplates is deprecated and no longer used. Use MeasureMergedCoaddSourcesConfig.inputCatalog.\n  warnings.warn(\"MeasureMergedCoaddSourcesConnections.defaultTemplates is deprecated and no longer used. \"\n", "levelno": 30, "levelname": "WARNING", "filename": "warnings.py", "pathname": "/cvmfs/sw.lsst.eu/linux-x86_64/lsst_distrib/w_2022_36/conda/envs/lsst-scipipe-4.1.0/lib/python3.10/warnings.py", "lineno": 109, "funcName": "_showwarnmsg", "process": 2439, "processName": "MainProcess", "MDC": {}}
{"name": "py.warnings", "asctime": "2022-09-08T21:03:00.647431+00:00", "message": "/cvmfs/sw.lsst.eu/linux-x86_64/lsst_distrib/w_2022_36/conda/envs/lsst-scipipe-4.1.0/share/eups/Linux64/pex_config/g71c1dbb2b5+34f28eb435/python/lsst/pex/config/configurableField.py:79: FutureWarning: Call to deprecated class LoadIndexedReferenceObjectsConfig. (This config is no longer used; it will be removed after v25. Please use LoadReferenceObjectsConfig instead.) -- Deprecated since version v25.0.\n  value = self._ConfigClass(__name=name, __at=at, __label=label, **storage)\n", "levelno": 30, "levelname": "WARNING", "filename": "warnings.py", "pathname": "/cvmfs/sw.lsst.eu/linux-x86_64/lsst_distrib/w_2022_36/conda/envs/lsst-scipipe-4.1.0/lib/python3.10/warnings.py", "lineno": 109, "funcName": "_showwarnmsg", "process": 2439, "processName": "MainProcess", "MDC": {}}
{"name": "py.warnings", "asctime": "2022-09-08T21:03:00.647822+00:00", "message": "/cvmfs/sw.lsst.eu/linux-x86_64/lsst_distrib/w_2022_36/conda/envs/lsst-scipipe-4.1.0/share/eups/Linux64/pex_config/g71c1dbb2b5+34f28eb435/python/lsst/pex/config/configurableField.py:359: FutureWarning: Call to deprecated class LoadIndexedReferenceObjectsConfig. (This config is no longer used; it will be removed after v25. Please use LoadReferenceObjectsConfig instead.) -- Deprecated since version v25.0.\n  value = oldValue.ConfigClass()\n", "levelno": 30, "levelname": "WARNING", "filename": "warnings.py", "pathname": "/cvmfs/sw.lsst.eu/linux-x86_64/lsst_distrib/w_2022_36/conda/envs/lsst-scipipe-4.1.0/lib/python3.10/warnings.py", "lineno": 109, "funcName": "_showwarnmsg", "process": 2439, "processName": "MainProcess", "MDC": {}}
{"name": "py.warnings", "asctime": "2022-09-08T21:03:05.385905+00:00", "message": "/cvmfs/sw.lsst.eu/linux-x86_64/lsst_distrib/w_2022_36/conda/envs/lsst-scipipe-4.1.0/share/eups/Linux64/pex_config/g71c1dbb2b5+34f28eb435/python/lsst/pex/config/configField.py:143: FutureWarning: Call to deprecated class LoadIndexedReferenceObjectsConfig. (This config is no longer used; it will be removed after v25. Please use LoadReferenceObjectsConfig instead.) -- Deprecated since version v25.0.\n  instance._storage[self.name] = self.dtype(__name=name, __at=at, __label=label)\n", "levelno": 30, "levelname": "WARNING", "filename": "warnings.py", "pathname": "/cvmfs/sw.lsst.eu/linux-x86_64/lsst_distrib/w_2022_36/conda/envs/lsst-scipipe-4.1.0/lib/python3.10/warnings.py", "lineno": 109, "funcName": "_showwarnmsg", "process": 2439, "processName": "MainProcess", "MDC": {}}
{"name": "lsst.jointcal", "asctime": "2022-09-08T21:03:05.405469+00:00", "message": "Only doing astrometry, but Colorterms are not applied for astrometry;applyColorTerms=True will be ignored.", "levelno": 30, "levelname": "WARNING", "filename": "jointcal.py", "pathname": "/cvmfs/sw.lsst.eu/linux-x86_64/lsst_distrib/w_2022_36/conda/envs/lsst-scipipe-4.1.0/share/eups/Linux64/jointcal/gba36e885db+c00ec0eebc/python/lsst/jointcal/jointcal.py", "lineno": 505, "funcName": "validate", "process": 2439, "processName": "MainProcess", "MDC": {}}
{"name": "py.warnings", "asctime": "2022-09-08T21:03:05.579749+00:00", "message": "/cvmfs/sw.lsst.eu/linux-x86_64/lsst_distrib/w_2022_36/conda/envs/lsst-scipipe-4.1.0/share/eups/Linux64/pex_config/g71c1dbb2b5+34f28eb435/python/lsst/pex/config/configurableField.py:79: FutureWarning: Call to deprecated class LoadIndexedReferenceObjectsConfig. (This config is no longer used; it will be removed after v25. Please use LoadReferenceObjectsConfig instead.) -- Deprecated since version v25.0.\n  value = self._ConfigClass(__name=name, __at=at, __label=label, **storage)\n", "levelno": 30, "levelname": "WARNING", "filename": "warnings.py", "pathname": "/cvmfs/sw.lsst.eu/linux-x86_64/lsst_distrib/w_2022_36/conda/envs/lsst-scipipe-4.1.0/lib/python3.10/warnings.py", "lineno": 109, "funcName": "_showwarnmsg", "process": 2439, "processName": "MainProcess", "MDC": {}}
{"name": "py.warnings", "asctime": "2022-09-08T21:03:05.580273+00:00", "message": "/cvmfs/sw.lsst.eu/linux-x86_64/lsst_distrib/w_2022_36/conda/envs/lsst-scipipe-4.1.0/share/eups/Linux64/pex_config/g71c1dbb2b5+34f28eb435/python/lsst/pex/config/configurableField.py:359: FutureWarning: Call to deprecated class LoadIndexedReferenceObjectsConfig. (This config is no longer used; it will be removed after v25. Please use LoadReferenceObjectsConfig instead.) -- Deprecated since version v25.0.\n  value = oldValue.ConfigClass()\n", "levelno": 30, "levelname": "WARNING", "filename": "warnings.py", "pathname": "/cvmfs/sw.lsst.eu/linux-x86_64/lsst_distrib/w_2022_36/conda/envs/lsst-scipipe-4.1.0/lib/python3.10/warnings.py", "lineno": 109, "funcName": "_showwarnmsg", "process": 2439, "processName": "MainProcess", "MDC": {}}
{"name": "lsst.jointcal", "asctime": "2022-09-08T21:03:05.758267+00:00", "message": "Only doing astrometry, but Colorterms are not applied for astrometry;applyColorTerms=True will be ignored.", "levelno": 30, "levelname": "WARNING", "filename": "jointcal.py", "pathname": "/cvmfs/sw.lsst.eu/linux-x86_64/lsst_distrib/w_2022_36/conda/envs/lsst-scipipe-4.1.0/share/eups/Linux64/jointcal/gba36e885db+c00ec0eebc/python/lsst/jointcal/jointcal.py", "lineno": 505, "funcName": "validate", "process": 2439, "processName": "MainProcess", "MDC": {}}
{"name": "lsst.jointcal", "asctime": "2022-09-08T21:03:06.299555+00:00", "message": "Only doing astrometry, but Colorterms are not applied for astrometry;applyColorTerms=True will be ignored.", "levelno": 30, "levelname": "WARNING", "filename": "jointcal.py", "pathname": "/cvmfs/sw.lsst.eu/linux-x86_64/lsst_distrib/w_2022_36/conda/envs/lsst-scipipe-4.1.0/share/eups/Linux64/jointcal/gba36e885db+c00ec0eebc/python/lsst/jointcal/jointcal.py", "lineno": 505, "funcName": "validate", "process": 2439, "processName": "MainProcess", "MDC": {}}
{"name": "lsst.ctrl.mpexec.cmdLineFwk", "asctime": "2022-09-08T21:10:05.874529+00:00", "message": "QuantumGraph contains 28263 quanta for 15 tasks, graph ID: '1662671387.7611961-2439'", "levelno": 20, "levelname": "INFO", "filename": "cmdLineFwk.py", "pathname": "/cvmfs/sw.lsst.eu/linux-x86_64/lsst_distrib/w_2022_36/conda/envs/lsst-scipipe-4.1.0/share/eups/Linux64/ctrl_mpexec/g5106228df7+1629eaad64/python/lsst/ctrl/mpexec/cmdLineFwk.py", "lineno": 581, "funcName": "makeGraph", "process": 2439, "processName": "MainProcess", "MDC": {}}
{"name": "lsst.ctrl.mpexec.cmdLineFwk", "asctime": "2022-09-12T18:59:18.629008+00:00", "message": "QuantumGraph contains 3 quanta for 1 tasks, graph ID: '1663009158.6226563-8071'", "levelno": 20, "levelname": "INFO", "filename": "cmdLineFwk.py", "pathname": "/cvmfs/sw.lsst.eu/linux-x86_64/lsst_distrib/w_2022_36/conda/envs/lsst-scipipe-4.1.0/share/eups/Linux64/ctrl_mpexec/g5106228df7+1629eaad64/python/lsst/ctrl/mpexec/cmdLineFwk.py", "lineno": 581, "funcName": "makeGraph", "process": 8071, "processName": "MainProcess", "MDC": {}}
{"name": "lsst.ctrl.mpexec.cmdLineFwk", "asctime": "2022-09-12T22:09:55.955849+00:00", "message": "QuantumGraph contains 264150 quanta for 9 tasks, graph ID: '1663020556.4365458-24519'", "levelno": 20, "levelname": "INFO", "filename": "cmdLineFwk.py", "pathname": "/cvmfs/sw.lsst.eu/linux-x86_64/lsst_distrib/w_2022_36/conda/envs/lsst-scipipe-4.1.0/share/eups/Linux64/ctrl_mpexec/g5106228df7+1629eaad64/python/lsst/ctrl/mpexec/cmdLineFwk.py", "lineno": 581, "funcName": "makeGraph", "process": 24519, "processName": "MainProcess", "MDC": {}}
{"name": "lsst.pipe.base.graphBuilder", "asctime": "2022-09-14T21:45:53.458035+00:00", "message": "Found 68 failed/incomplete quanta for task with label 'subtractImages' that will need to be clobbered during execution.", "levelno": 20, "levelname": "INFO", "filename": "graphBuilder.py", "pathname": "/cvmfs/sw.lsst.eu/linux-x86_64/lsst_distrib/w_2022_36/conda/envs/lsst-scipipe-4.1.0/share/eups/Linux64/pipe_base/g646899f3d4+4ec38301be/python/lsst/pipe/base/graphBuilder.py", "lineno": 1101, "funcName": "resolveDatasetRefs", "process": 72101, "processName": "MainProcess", "MDC": {}}
{"name": "lsst.ctrl.mpexec.cmdLineFwk", "asctime": "2022-09-14T21:45:58.374000+00:00", "message": "QuantumGraph contains 345 quanta for 9 tasks, graph ID: '1663191958.17188-72101'", "levelno": 20, "levelname": "INFO", "filename": "cmdLineFwk.py", "pathname": "/cvmfs/sw.lsst.eu/linux-x86_64/lsst_distrib/w_2022_36/conda/envs/lsst-scipipe-4.1.0/share/eups/Linux64/ctrl_mpexec/g5106228df7+1629eaad64/python/lsst/ctrl/mpexec/cmdLineFwk.py", "lineno": 581, "funcName": "makeGraph", "process": 72101, "processName": "MainProcess", "MDC": {}}
{"name": "lsst.ctrl.mpexec.cmdLineFwk", "asctime": "2022-09-15T17:15:06.087004+00:00", "message": "QuantumGraph contains 86291 quanta for 11 tasks, graph ID: '1663262090.4167511-66783'", "levelno": 20, "levelname": "INFO", "filename": "cmdLineFwk.py", "pathname": "/cvmfs/sw.lsst.eu/linux-x86_64/lsst_distrib/w_2022_36/conda/envs/lsst-scipipe-4.1.0/share/eups/Linux64/ctrl_mpexec/g5106228df7+1629eaad64/python/lsst/ctrl/mpexec/cmdLineFwk.py", "lineno": 581, "funcName": "makeGraph", "process": 66783, "processName": "MainProcess", "MDC": {}}
{"name": "lsst.ctrl.mpexec.cmdLineFwk", "asctime": "2022-09-16T18:27:15.059889+00:00", "message": "QuantumGraph contains 864 quanta for 2 tasks, graph ID: '1663352833.4770906-14431'", "levelno": 20, "levelname": "INFO", "filename": "cmdLineFwk.py", "pathname": "/cvmfs/sw.lsst.eu/linux-x86_64/lsst_distrib/w_2022_36/conda/envs/lsst-scipipe-4.1.0/share/eups/Linux64/ctrl_mpexec/g5106228df7+1629eaad64/python/lsst/ctrl/mpexec/cmdLineFwk.py", "lineno": 581, "funcName": "makeGraph", "process": 14431, "processName": "MainProcess", "MDC": {}}
{"name": "lsst.ctrl.mpexec.cmdLineFwk", "asctime": "2022-09-16T18:28:16.746408+00:00", "message": "QuantumGraph contains 6 quanta for 1 tasks, graph ID: '1663352896.7407632-15550'", "levelno": 20, "levelname": "INFO", "filename": "cmdLineFwk.py", "pathname": "/cvmfs/sw.lsst.eu/linux-x86_64/lsst_distrib/w_2022_36/conda/envs/lsst-scipipe-4.1.0/share/eups/Linux64/ctrl_mpexec/g5106228df7+1629eaad64/python/lsst/ctrl/mpexec/cmdLineFwk.py", "lineno": 581, "funcName": "makeGraph", "process": 15550, "processName": "MainProcess", "MDC": {}}
